Workbook

Sheet Documentation
A1: QuantExt Rate Helpers - Example / Regression Coverage
A3: This workbook exercises the ten QuantExt rate helpers exported to QuantLibXL.
A4: It is organised as:
A5: - Setup : evaluation date, market quotes, indices and a discount curve.
A6: - OIS_Helpers : qlQxOISRateHelper, qlQxDatedOISRateHelper, qlAverageOISRateHelper.
A7: - Basis_Helpers : qlBasisTwoSwapHelper, qlSubPeriodsSwapHelper, qlTenorBasisSwapHelper.
A8: - CrossCcy_Helpers : the four cross-currency helpers.
A10: Each helper sheet lists its inputs in labelled cells and calls the function in the
A11: Formula' row. Recalculate (F9) with the QuantLibXL addin loaded to populate the
A12: object ids. The named input cells are referenced by the formulas so values can be
A13: changed in one place.
A15: Ticket: ACADIAQPR-14118

Sheet Setup
A1: Setup: evaluation date, quotes, indices and discount curve
A3: Evaluation date | B3: =_xll.qlSettingsSetEvaluationDate(DATE(2024,1,15),FALSE) -> TRUE | F3: =_xll.ohRangeRetrieveError(B3)
A5: Object | B5: Id | C5: Formula | F5: Error
A6: Fixed rate quote | B6: RateQuote | C6: =_xll.qlSimpleQuote("RateQuote",0.03,0,FALSE,$C$3) -> RateQuote#0000 | F6: =_xll.ohRangeRetrieveError(C6)
A7: Spread quote | B7: SpreadQuote | C7: =_xll.qlSimpleQuote("SpreadQuote",0.001,0,FALSE,$C$3) -> SpreadQuote#0000 | F7: =_xll.ohRangeRetrieveError(C7)
A8: ON spread quote | B8: OnSpreadQuote | C8: =_xll.qlSimpleQuote("OnSpreadQuote",0,0,FALSE,$C$3) -> OnSpreadQuote#0000 | F8: =_xll.ohRangeRetrieveError(C8)
A9: Spot FX quote | B9: SpotFxQuote | C9: =_xll.qlSimpleQuote("SpotFxQuote",1.1,0,FALSE,$C$3) -> SpotFxQuote#0000 | F9: =_xll.ohRangeRetrieveError(C9)
A13: Object | B13: Id | C13: Formula | F13: Error
A14: Overnight index (EUR) | B14: OnIndex | C14: =_xll.qlEonia("OnIndex","",FALSE,$C$3) -> OnIndex#0000 | F14: =_xll.ohRangeRetrieveError(C14)
A15: Ibor index 6M (EUR) | B15: Ibor6M | C15: =_xll.qlEuribor("Ibor6M","6M","",FALSE,$C$3) -> Ibor6M#0000 | F15: =_xll.ohRangeRetrieveError(C15)
A16: Ibor index 3M (EUR) | B16: Ibor3M | C16: =_xll.qlEuribor("Ibor3M","3M","",FALSE,$C$3) -> Ibor3M#0000 | F16: =_xll.ohRangeRetrieveError(C16)
A17: Ibor index 3M (USD) | B17: UsdIbor3M | C17: =_xll.qlLibor("UsdIbor3M","USD","3M","",FALSE,$C$3) -> UsdIbor3M#0000 | F17: =_xll.ohRangeRetrieveError(C17)
A18: Discount curve (EUR) | B18: EurDiscount | C18: =_xll.qlFlatForward("EurDiscount",0,"TARGET",0.03,"Actual/360","Continuous","Annual",FALSE,$C$3) -> EurDiscount#0000 | F18: =_xll.ohRangeRetrieveError(C18)
A19: Discount curve (USD) | B19: UsdDiscount | C19: =_xll.qlFlatForward("UsdDiscount",0,"US settlement",0.04,"Actual/360","Continuous","Annual",FALSE,$C$3) -> UsdDiscount#0000 | F19: =_xll.ohRangeRetrieveError(C19)

Sheet OIS_Helpers
A1: Overnight-indexed-swap rate helpers
D2: Error
A3: qlQxOISRateHelper
A4: Argument | B4: Value
A5: SettlDays | B5: 2
A6: Tenor | B6: 10Y
A7: FixedRate | B7: =Setup!B6 -> RateQuote
A8: ONIndex | B8: =Setup!B14 -> OnIndex
A9: FixedDayCounter | B9: Actual/360
A10: FixedCalendar | B10: TARGET
A11: PaymentLag | B11: 0
A12: PaymentFrequency | B12: Annual
A13: FixedConvention | B13: Following
A14: PaymentAdjustment | B14: Following
A15: Rule | B15: Backward
A16: DiscountingCurve | D16: (left empty: wrapper sets indexGiven=true, so a discount curve here would over-specify the helper)
A17: TelescopicValueDates | B17: FALSE
A18: Formula | B18: =_xll.qlQxOISRateHelper("QxOISRateHelper",B5,B6,B7,B8,B9,B10,B11,B12,B13,B14,B15,B16,B17,TRUE,FALSE,Setup!$C$3:$C$19) -> QxOISRateHelper#0000 | D18: =_xll.ohRangeRetrieveError(B18)
A20: qlQxDatedOISRateHelper
A21: Argument | B21: Value
A22: StartDate | B22: =DATE(2024,1,17) -> 45308
A23: EndDate | B23: =DATE(2034,1,17) -> 48961
A24: FixedRate | B24: =Setup!B6 -> RateQuote
A25: ONIndex | B25: =Setup!B14 -> OnIndex
A26: FixedDayCounter | B26: Actual/360
A27: FixedCalendar | B27: TARGET
A28: PaymentLag | B28: 0
A29: PaymentFrequency | B29: Annual
A30: FixedConvention | B30: Following
A31: PaymentAdjustment | B31: Following
A32: Rule | B32: Backward
A33: DiscountingCurve | D33: (left empty: wrapper sets indexGiven=true, so a discount curve here would over-specify the helper)
A34: TelescopicValueDates | B34: FALSE
A35: Formula | B35: =_xll.qlQxDatedOISRateHelper("QxDatedOISRateHelper",B22,B23,B24,B25,B26,B27,B28,B29,B30,B31,B32,B33,B34,FALSE,Setup!$C$3:$C$19) -> QxDatedOISRateHelper#0000 | D35: =_xll.ohRangeRetrieveError(B35)
A37: qlAverageOISRateHelper
A38: Argument | B38: Value
A39: FixedRate | B39: =Setup!B6 -> RateQuote
A40: SpotLagTenor | B40: 2D
A41: SwapTenor | B41: 10Y
A42: FixedTenor | B42: 1Y
...

Sheet Basis_Helpers
A1: Basis / sub-period / tenor-basis rate helpers
D2: Error
A3: qlBasisTwoSwapHelper
A4: Argument | B4: Value
A5: Spread | B5: =Setup!B7 -> SpreadQuote
A6: SwapTenor | B6: 10Y
A7: Calendar | B7: TARGET
A8: LongFixedFrequency | B8: Annual
A9: LongFixedConvention | B9: Following
A10: LongFixedDayCount | B10: Actual/360
A11: LongIndex | B11: =Setup!B15 -> Ibor6M
A12: ShortFixedFrequency | B12: Annual
A13: ShortFixedConvention | B13: Following
A14: ShortFixedDayCount | B14: Actual/360
A15: ShortIndex | B15: =Setup!B16 -> Ibor3M
A16: LongMinusShort | B16: TRUE
A17: DiscountingCurve | D17: (left empty: wrapper sets indexGiven=true, so a discount curve here would over-specify the helper)
A18: Formula | B18: =_xll.qlBasisTwoSwapHelper("BasisTwoSwapHelper",B5,B6,B7,B8,B9,B10,B11,B12,B13,B14,B15,B16,B17,FALSE,Setup!$C$3:$C$19) -> #NUM! | D18: =_xll.ohRangeRetrieveError(B18) -> qlBasisTwoSwapHelper - input value is vector or matrix, expected scalar
A20: qlSubPeriodsSwapHelper
A21: Argument | B21: Value
A22: Spread | B22: =Setup!B7 -> SpreadQuote
A23: SwapTenor | B23: 10Y
A24: FixedTenor | B24: 1Y
A25: FixedCalendar | B25: TARGET
A26: FixedDayCount | B26: Actual/360
A27: FixedConvention | B27: Following
A28: FloatPayTenor | B28: 3M
A29: IborIndex | B29: =Setup!B16 -> Ibor3M
A30: FloatDayCount | B30: Actual/360
A31: DiscountingCurve | B31: =Setup!B18 -> EurDiscount
A32: CouponType | B32: Compounding
A33: Formula | B33: =_xll.qlSubPeriodsSwapHelper("SubPeriodsSwapHelper",B22,B23,B24,B25,B26,B27,B28,B29,B30,B31,B32,FALSE,Setup!$C$3:$C$19) -> SubPeriodsSwapHelper#0000 | D33: =_xll.ohRangeRetrieveError(B33)
A35: qlTenorBasisSwapHelper
A36: Argument | B36: Value
A37: Spread | B37: =Setup!B7 -> SpreadQuote
A38: SwapTenor | B38: 10Y
A39: PayIndex | B39: =Setup!B15 -> Ibor6M
A40: ReceiveIndex | B40: =Setup!B16 -> Ibor3M
A41: DiscountingCurve | D41: (left empty: wrapper sets indexGiven=true, so a discount curve here would over-specify the helper)
A42: SpreadOnRec | B42: TRUE
...

Sheet CrossCcy_Helpers
A1: Cross-currency rate helpers
D2: Error
A3: qlCrossCcyBasisSwapHelper
A4: Argument | B4: Value
A5: SpreadQuote | B5: =Setup!B7 -> SpreadQuote
A6: SpotFX | B6: =Setup!B9 -> SpotFxQuote
A7: SettlementDays | B7: 2
A8: SettlementCalendar | B8: TARGET
A9: SwapTenor | B9: 10Y
A10: RollConvention | B10: Following
A11: FlatIndex | B11: =Setup!B16 -> Ibor3M
A12: SpreadIndex | B12: =Setup!B17 -> UsdIbor3M
A13: FlatDiscountCurve | D13: (left empty: wrapper sets indexGiven=true, so a discount curve here would over-specify the helper)
A14: SpreadDiscountCurve | B14: =Setup!B19 -> UsdDiscount
A15: EndOfMonth | B15: FALSE
A16: FlatIsDomestic | B16: TRUE
A17: Formula | B17: =_xll.qlCrossCcyBasisSwapHelper("CrossCcyBasisSwapHelper",B5,B6,B7,B8,B9,B10,B11,B12,B13,B14,B15,B16,FALSE,Setup!$C$3:$C$19) -> #NUM! | D17: =_xll.ohRangeRetrieveError(B17) -> qlCrossCcyBasisSwapHelper - input value is vector or matrix, expected scalar
A19: qlCrossCcyBasisMtMResetSwapHelper
A20: Argument | B20: Value
A21: SpreadQuote | B21: =Setup!B7 -> SpreadQuote
A22: SpotFX | B22: =Setup!B9 -> SpotFxQuote
A23: SettlementDays | B23: 2
A24: SettlementCalendar | B24: TARGET
A25: SwapTenor | B25: 10Y
A26: RollConvention | B26: Following
A27: ForeignCcyIndex | B27: =Setup!B17 -> UsdIbor3M
A28: DomesticCcyIndex | B28: =Setup!B16 -> Ibor3M
A29: ForeignCcyDiscountCurve | D29: (left empty: wrapper sets indexGiven=true, so a discount curve here would over-specify the helper)
A30: DomesticCcyDiscountCurve | B30: =Setup!B18 -> EurDiscount
A31: EndOfMonth | B31: FALSE
A32: SpreadOnForeignCcy | B32: TRUE
A33: Formula | B33: =_xll.qlCrossCcyBasisMtMResetSwapHelper("CrossCcyBasisMtMResetSwapHelper",B21,B22,B23,B24,B25,B26,B27,B28,B29,B30,B31,B32,FALSE,Setup!$C$3:$C$19) -> #NUM! | D33: =_xll.ohRangeRetrieveError(B33) -> qlCrossCcyBasisMtMResetSwapHelper - input value is vector or matrix, expected scalar
A35: qlCrossCcyFixFloatSwapHelper
A36: Argument | B36: Value
A37: Rate | B37: =Setup!B6 -> RateQuote
A38: SpotFx | B38: =Setup!B9 -> SpotFxQuote
A39: SettlementDays | B39: 2
A40: PaymentCalendar | B40: TARGET
A41: PaymentConvention | B41: Following
A42: Tenor | B42: 10Y
...
