Workbook

Sheet MarketData
A1: Cross_Currency_Swap_rebalancing: market data and fixings (as of 2019-12-30)
A2: Quotes taken from Input\market.txt for every quote referenced by Input\curveconfig.xml; fixings from Input\fixings.txt.
A4: Evaluation date | B4: =_xll.qlSettingsSetEvaluationDate(DATE(2019,12,30),FALSE) -> TRUE | C4: =_xll.ohRangeRetrieveError(B4)
A6: Curve | B6: Segment | C6: Market quote | D6: Value | E6: Quote object | F6: Error | H6: Fixing date | I6: Index | J6: Value
A7: EUR-EONIA | B7: Deposit | C7: MM/RATE/EUR/0D/1D | D7: -0.00454 | E7: =_xll.qlSimpleQuote(SUBSTITUTE(A7&"_"&C7,"/","_"),D7,0,FALSE,$B$4) -> EUR-EONIA_MM_RATE_EUR_0D_1D#0000 | F7: =_xll.ohRangeRetrieveError(E7) | H7: =DATE(2019,8,1) -> 43678 | I7: FX-ECB-EUR-USD | J7: 1.1037
A8: EUR-EONIA | B8: OIS | C8: IR_SWAP/RATE/EUR/2D/1D/1W | D8: -0.00468 | E8: =_xll.qlSimpleQuote(SUBSTITUTE(A8&"_"&C8,"/","_"),D8,0,FALSE,$B$4) -> EUR-EONIA_IR_SWAP_RATE_EUR_2D_1D_1W#0000 | F8: =_xll.ohRangeRetrieveError(E8) | H8: =DATE(2019,8,3) -> 43680 | I8: USD-LIBOR-6M | J8: 0.0222688
A9: EUR-EONIA | B9: OIS | C9: IR_SWAP/RATE/EUR/2D/1D/2W | D9: -0.0045 | E9: =_xll.qlSimpleQuote(SUBSTITUTE(A9&"_"&C9,"/","_"),D9,0,FALSE,$B$4) -> EUR-EONIA_IR_SWAP_RATE_EUR_2D_1D_2W#0000 | F9: =_xll.ohRangeRetrieveError(E9) | H9: =DATE(2019,8,1) -> 43678 | I9: USD-LIBOR-6M | J9: 0.0222688
A10: EUR-EONIA | B10: OIS | C10: IR_SWAP/RATE/EUR/2D/1D/3W | D10: -0.00467 | E10: =_xll.qlSimpleQuote(SUBSTITUTE(A10&"_"&C10,"/","_"),D10,0,FALSE,$B$4) -> EUR-EONIA_IR_SWAP_RATE_EUR_2D_1D_3W#0000 | F10: =_xll.ohRangeRetrieveError(E10) | H10: =DATE(2019,8,1) -> 43678 | I10: EUR-EURIBOR-6M | J10: -0.00363
A11: EUR-EONIA | B11: OIS | C11: IR_SWAP/RATE/EUR/2D/1D/1M | D11: -0.004482 | E11: =_xll.qlSimpleQuote(SUBSTITUTE(A11&"_"&C11,"/","_"),D11,0,FALSE,$B$4) -> EUR-EONIA_IR_SWAP_RATE_EUR_2D_1D_1M#0000 | F11: =_xll.ohRangeRetrieveError(E11)
A12: EUR-EONIA | B12: OIS | C12: IR_SWAP/RATE/EUR/2D/1D/2M | D12: -0.004472 | E12: =_xll.qlSimpleQuote(SUBSTITUTE(A12&"_"&C12,"/","_"),D12,0,FALSE,$B$4) -> EUR-EONIA_IR_SWAP_RATE_EUR_2D_1D_2M#0000 | F12: =_xll.ohRangeRetrieveError(E12) | H12: The 2019-08-03 USD-LIBOR-6M fixing falls on a Saturday and is not used by the trade.
A13: EUR-EONIA | B13: OIS | C13: IR_SWAP/RATE/EUR/2D/1D/3M | D13: -0.004466 | E13: =_xll.qlSimpleQuote(SUBSTITUTE(A13&"_"&C13,"/","_"),D13,0,FALSE,$B$4) -> EUR-EONIA_IR_SWAP_RATE_EUR_2D_1D_3M#0000 | F13: =_xll.ohRangeRetrieveError(E13)
A14: EUR-EONIA | B14: OIS | C14: IR_SWAP/RATE/EUR/2D/1D/4M | D14: -0.004465 | E14: =_xll.qlSimpleQuote(SUBSTITUTE(A14&"_"&C14,"/","_"),D14,0,FALSE,$B$4) -> EUR-EONIA_IR_SWAP_RATE_EUR_2D_1D_4M#0000 | F14: =_xll.ohRangeRetrieveError(E14)
A15: EUR-EONIA | B15: OIS | C15: IR_SWAP/RATE/EUR/2D/1D/5M | D15: -0.004467 | E15: =_xll.qlSimpleQuote(SUBSTITUTE(A15&"_"&C15,"/","_"),D15,0,FALSE,$B$4) -> EUR-EONIA_IR_SWAP_RATE_EUR_2D_1D_5M#0000 | F15: =_xll.ohRangeRetrieveError(E15)
A16: EUR-EONIA | B16: OIS | C16: IR_SWAP/RATE/EUR/2D/1D/6M | D16: -0.00451 | E16: =_xll.qlSimpleQuote(SUBSTITUTE(A16&"_"&C16,"/","_"),D16,0,FALSE,$B$4) -> EUR-EONIA_IR_SWAP_RATE_EUR_2D_1D_6M#0000 | F16: =_xll.ohRangeRetrieveError(E16)
A17: EUR-EONIA | B17: OIS | C17: IR_SWAP/RATE/EUR/2D/1D/7M | D17: -0.004479 | E17: =_xll.qlSimpleQuote(SUBSTITUTE(A17&"_"&C17,"/","_"),D17,0,FALSE,$B$4) -> EUR-EONIA_IR_SWAP_RATE_EUR_2D_1D_7M#0000 | F17: =_xll.ohRangeRetrieveError(E17)
A18: EUR-EONIA | B18: OIS | C18: IR_SWAP/RATE/EUR/2D/1D/8M | D18: -0.004484 | E18: =_xll.qlSimpleQuote(SUBSTITUTE(A18&"_"&C18,"/","_"),D18,0,FALSE,$B$4) -> EUR-EONIA_IR_SWAP_RATE_EUR_2D_1D_8M#0000 | F18: =_xll.ohRangeRetrieveError(E18)
A19: EUR-EONIA | B19: OIS | C19: IR_SWAP/RATE/EUR/2D/1D/9M | D19: -0.004488 | E19: =_xll.qlSimpleQuote(SUBSTITUTE(A19&"_"&C19,"/","_"),D19,0,FALSE,$B$4) -> EUR-EONIA_IR_SWAP_RATE_EUR_2D_1D_9M#0000 | F19: =_xll.ohRangeRetrieveError(E19)
A20: EUR-EONIA | B20: OIS | C20: IR_SWAP/RATE/EUR/2D/1D/10M | D20: -0.004493 | E20: =_xll.qlSimpleQuote(SUBSTITUTE(A20&"_"&C20,"/","_"),D20,0,FALSE,$B$4) -> EUR-EONIA_IR_SWAP_RATE_EUR_2D_1D_10M#0000 | F20: =_xll.ohRangeRetrieveError(E20)
A21: EUR-EONIA | B21: OIS | C21: IR_SWAP/RATE/EUR/2D/1D/11M | D21: -0.004494 | E21: =_xll.qlSimpleQuote(SUBSTITUTE(A21&"_"&C21,"/","_"),D21,0,FALSE,$B$4) -> EUR-EONIA_IR_SWAP_RATE_EUR_2D_1D_11M#0000 | F21: =_xll.ohRangeRetrieveError(E21)
A22: EUR-EONIA | B22: OIS | C22: IR_SWAP/RATE/EUR/2D/1D/1Y | D22: -0.004495 | E22: =_xll.qlSimpleQuote(SUBSTITUTE(A22&"_"&C22,"/","_"),D22,0,FALSE,$B$4) -> EUR-EONIA_IR_SWAP_RATE_EUR_2D_1D_1Y#0000 | F22: =_xll.ohRangeRetrieveError(E22)
A23: EUR-EONIA | B23: OIS | C23: IR_SWAP/RATE/EUR/2D/1D/15M | D23: -0.004485 | E23: =_xll.qlSimpleQuote(SUBSTITUTE(A23&"_"&C23,"/","_"),D23,0,FALSE,$B$4) -> EUR-EONIA_IR_SWAP_RATE_EUR_2D_1D_15M#0000 | F23: =_xll.ohRangeRetrieveError(E23)
A24: EUR-EONIA | B24: OIS | C24: IR_SWAP/RATE/EUR/2D/1D/18M | D24: -0.00448 | E24: =_xll.qlSimpleQuote(SUBSTITUTE(A24&"_"&C24,"/","_"),D24,0,FALSE,$B$4) -> EUR-EONIA_IR_SWAP_RATE_EUR_2D_1D_18M#0000 | F24: =_xll.ohRangeRetrieveError(E24)
... A209: USD-LIBOR-6M | B209: Tenor Basis Swap | C209: BASIS_SWAP/BASIS_SPREAD/3M/6M/USD/30Y | D209: 0.0008754 | E209: =_xll.qlSimpleQuote(SUBSTITUTE(A209&"_"&C209,"/","_"),D209,0,FALSE,$B$4) -> USD-LIBOR-6M_BASIS_SWAP_BASIS_SPREAD_3M_6M_USD_30Y#0000 | F209: =_xll.ohRangeRetrieveError(E209)
A211: Quote objects | B211: =COUNTA(E7:E209) -> 203
A212: Errors | B212: =SUMPRODUCT(--(F7:F209<>"")) -> 0

Sheet Indexes
A1: Cross_Currency_Swap_rebalancing: curve handles, indexes and fixings
A2: Indexes forecast on relinkable curve handles, which are linked to the bootstrapped curves in later sheets.
A4: Curve handle | B4: Object | C4: Error
A5: USD-FedFunds | B5: =_xll.qlRelinkableHandleYieldTermStructure("H_USD-FedFunds","",FALSE,MarketData!$B$4) -> H_USD-FedFunds#0000 | C5: =_xll.ohRangeRetrieveError(B5)
A6: EUR-EONIA | B6: =_xll.qlRelinkableHandleYieldTermStructure("H_EUR-EONIA","",FALSE,MarketData!$B$4) -> H_EUR-EONIA#0000 | C6: =_xll.ohRangeRetrieveError(B6)
A7: USD-LIBOR-3M | B7: =_xll.qlRelinkableHandleYieldTermStructure("H_USD-LIBOR-3M","",FALSE,MarketData!$B$4) -> H_USD-LIBOR-3M#0000 | C7: =_xll.ohRangeRetrieveError(B7)
A8: USD-LIBOR-6M | B8: =_xll.qlRelinkableHandleYieldTermStructure("H_USD-LIBOR-6M","",FALSE,MarketData!$B$4) -> H_USD-LIBOR-6M#0000 | C8: =_xll.ohRangeRetrieveError(B8)
A9: EUR-EURIBOR-6M | B9: =_xll.qlRelinkableHandleYieldTermStructure("H_EUR-EURIBOR-6M","",FALSE,MarketData!$B$4) -> H_EUR-EURIBOR-6M#0000 | C9: =_xll.ohRangeRetrieveError(B9)
A10: EUR-EURIBOR-3M | B10: =_xll.qlRelinkableHandleYieldTermStructure("H_EUR-EURIBOR-3M","",FALSE,MarketData!$B$4) -> H_EUR-EURIBOR-3M#0000 | C10: =_xll.ohRangeRetrieveError(B10)
A11: EUR-IN-USD | B11: =_xll.qlRelinkableHandleYieldTermStructure("H_EUR-IN-USD","",FALSE,MarketData!$B$4) -> H_EUR-IN-USD#0000 | C11: =_xll.ohRangeRetrieveError(B11)
A13: Index (ORE name) | B13: Object | C13: Error | D13: Name | E13: Fixing calendar | F13: Fixing days | G13: Day counter | H13: Value date of 2019-08-01
A14: USD-FedFunds | B14: =_xll.qlOvernightIndex("USD-FedFunds","FedFunds",0,"USD","UnitedStates::FederalReserve","Actual/360",$B$5,FALSE,MarketData!$B$4) -> USD-FedFunds#0000 | C14: =_xll.ohRangeRetrieveError(B14) | D14: =_xll.qlIndexName(B14) -> FedFundsON Actual/360 | E14: =_xll.qlIndexFixingCalendar(B14) -> Federal Reserve Bankwire System | F14: =_xll.qlInterestRateIndexFixingDays(B14) -> 0 | G14: =_xll.qlInterestRateIndexDayCounter(B14) -> Actual/360 | H14: =_xll.qlInterestRateIndexValueDate(B14,DATE(2019,8,1)) -> 43678
A15: EUR-EONIA | B15: =_xll.qlEonia("EUR-EONIA",$B$6,FALSE,MarketData!$B$4) -> EUR-EONIA#0000 | C15: =_xll.ohRangeRetrieveError(B15) | D15: =_xll.qlIndexName(B15) -> EoniaON Actual/360 | E15: =_xll.qlIndexFixingCalendar(B15) -> TARGET | F15: =_xll.qlInterestRateIndexFixingDays(B15) -> 0 | G15: =_xll.qlInterestRateIndexDayCounter(B15) -> Actual/360 | H15: =_xll.qlInterestRateIndexValueDate(B15,DATE(2019,8,1)) -> 43678
A16: USD-LIBOR-3M | B16: =_xll.qlLibor("USD-LIBOR-3M","USD","3M",$B$7,FALSE,MarketData!$B$4) -> USD-LIBOR-3M#0000 | C16: =_xll.ohRangeRetrieveError(B16) | D16: =_xll.qlIndexName(B16) -> USDLibor3M Actual/360 | E16: =_xll.qlIndexFixingCalendar(B16) -> London stock exchange | F16: =_xll.qlInterestRateIndexFixingDays(B16) -> 2 | G16: =_xll.qlInterestRateIndexDayCounter(B16) -> Actual/360 | H16: =_xll.qlInterestRateIndexValueDate(B16,DATE(2019,8,1)) -> 43682
A17: USD-LIBOR-6M | B17: =_xll.qlLibor("USD-LIBOR-6M","USD","6M",$B$8,FALSE,MarketData!$B$4) -> USD-LIBOR-6M#0000 | C17: =_xll.ohRangeRetrieveError(B17) | D17: =_xll.qlIndexName(B17) -> USDLibor6M Actual/360 | E17: =_xll.qlIndexFixingCalendar(B17) -> London stock exchange | F17: =_xll.qlInterestRateIndexFixingDays(B17) -> 2 | G17: =_xll.qlInterestRateIndexDayCounter(B17) -> Actual/360 | H17: =_xll.qlInterestRateIndexValueDate(B17,DATE(2019,8,1)) -> 43682
A18: EUR-EURIBOR-3M | B18: =_xll.qlEuribor("EUR-EURIBOR-3M","3M",$B$10,FALSE,MarketData!$B$4) -> EUR-EURIBOR-3M#0000 | C18: =_xll.ohRangeRetrieveError(B18) | D18: =_xll.qlIndexName(B18) -> Euribor3M Actual/360 | E18: =_xll.qlIndexFixingCalendar(B18) -> TARGET | F18: =_xll.qlInterestRateIndexFixingDays(B18) -> 2 | G18: =_xll.qlInterestRateIndexDayCounter(B18) -> Actual/360 | H18: =_xll.qlInterestRateIndexValueDate(B18,DATE(2019,8,1)) -> 43682
A19: EUR-EURIBOR-6M | B19: =_xll.qlEuribor("EUR-EURIBOR-6M","6M",$B$9,FALSE,MarketData!$B$4) -> EUR-EURIBOR-6M#0000 | C19: =_xll.ohRangeRetrieveError(B19) | D19: =_xll.qlIndexName(B19) -> Euribor6M Actual/360 | E19: =_xll.qlIndexFixingCalendar(B19) -> TARGET | F19: =_xll.qlInterestRateIndexFixingDays(B19) -> 2 | G19: =_xll.qlInterestRateIndexDayCounter(B19) -> Actual/360 | H19: =_xll.qlInterestRateIndexValueDate(B19,DATE(2019,8,1)) -> 43682
A21: FX index | B21: Object | C21: Error | D21: Name | E21: Source | F21: Target
A22: FX-ECB-EUR-USD | B22: =_xll.qlFxIndex("FX-ECB-EUR-USD","ECB",2,"EUR","USD","TARGET",MarketData!$E$93,$B$11,$B$5,TRUE,FALSE,MarketData!$B$4) -> FX-ECB-EUR-USD#0000 | C22: =_xll.ohRangeRetrieveError(B22) | D22: =_xll.qlIndexName(B22) -> ECB EUR/USD | E22: =_xll.qlFxIndexSourceCurrency(B22) -> EUR | F22: =_xll.qlFxIndexTargetCurrency(B22) -> USD | H22: Inverse spot quote | I22: =_xll.qlSimpleQuote("FX_RATE_USD_EUR",1/MarketData!$D$93,0,FALSE,MarketData!$B$4) -> FX_RATE_USD_EUR#0000
A23: FX-ECB-USD-EUR (inverse, reads EUR/USD fixings) | B23: =_xll.qlFxIndex("FX-ECB-USD-EUR","ECB",2,"USD","EUR","TARGET",I22,$B$5,$B$11,TRUE,FALSE,MarketData!$B$4) -> FX-ECB-USD-EUR#0000 | C23: =_xll.ohRangeRetrieveError(B23) | D23: =_xll.qlIndexName(B23) -> ECB USD/EUR | E23: =_xll.qlFxIndexSourceCurrency(B23) -> USD | F23: =_xll.qlFxIndexTargetCurrency(B23) -> EUR | H23: USD/EUR fixing 2019-08-01 | I23: =_xll.qlIndexFixing(B23,DATE(2019,8,1),FALSE,B31) -> 0.90604331 | J23: =I23-1/1.1037 -> 0
A25: Fixing date | B25: Index | C25: Value | D25: Add fixing | E25: Error | F25: Read back | G25: Difference
A26: =MarketData!H7 -> 43678 | B26: =MarketData!I7 -> FX-ECB-EUR-USD | C26: =MarketData!J7 -> 1.1037 | D26: =IF(WEEKDAY(A26,2)>5,"skipped (weekend)",_xll.qlIndexAddFixings(INDEX($B$14:$B$22,MATCH(B26,$A$14:$A$22,0)),A26,C26,TRUE)) -> TRUE | E26: =IF(WEEKDAY(A26,2)>5,"",_xll.ohRangeRetrieveError(D26)) | F26: =IF(WEEKDAY(A26,2)>5,"",_xll.qlIndexFixing(INDEX($B$14:$B$22,MATCH(B26,$A$14:$A$22,0)),A26,FALSE,D26)) -> 1.1037 | G26: =IF(WEEKDAY(A26,2)>5,"",F26-C26) -> 0
A27: =MarketData!H8 -> 43680 | B27: =MarketData!I8 -> USD-LIBOR-6M | C27: =MarketData!J8 -> 0.0222688 | D27: =IF(WEEKDAY(A27,2)>5,"skipped (weekend)",_xll.qlIndexAddFixings(INDEX($B$14:$B$22,MATCH(B27,$A$14:$A$22,0)),A27,C27,TRUE)) -> skipped (weekend) | E27: =IF(WEEKDAY(A27,2)>5,"",_xll.ohRangeRetrieveError(D27)) | F27: =IF(WEEKDAY(A27,2)>5,"",_xll.qlIndexFixing(INDEX($B$14:$B$22,MATCH(B27,$A$14:$A$22,0)),A27,FALSE,D27)) | G27: =IF(WEEKDAY(A27,2)>5,"",F27-C27)
A28: =MarketData!H9 -> 43678 | B28: =MarketData!I9 -> USD-LIBOR-6M | C28: =MarketData!J9 -> 0.0222688 | D28: =IF(WEEKDAY(A28,2)>5,"skipped (weekend)",_xll.qlIndexAddFixings(INDEX($B$14:$B$22,MATCH(B28,$A$14:$A$22,0)),A28,C28,TRUE)) -> TRUE | E28: =IF(WEEKDAY(A28,2)>5,"",_xll.ohRangeRetrieveError(D28)) | F28: =IF(WEEKDAY(A28,2)>5,"",_xll.qlIndexFixing(INDEX($B$14:$B$22,MATCH(B28,$A$14:$A$22,0)),A28,FALSE,D28)) -> 0.0222688 | G28: =IF(WEEKDAY(A28,2)>5,"",F28-C28) -> 0
A29: =MarketData!H10 -> 43678 | B29: =MarketData!I10 -> EUR-EURIBOR-6M | C29: =MarketData!J10 -> -0.00363 | D29: =IF(WEEKDAY(A29,2)>5,"skipped (weekend)",_xll.qlIndexAddFixings(INDEX($B$14:$B$22,MATCH(B29,$A$14:$A$22,0)),A29,C29,TRUE)) -> TRUE | E29: =IF(WEEKDAY(A29,2)>5,"",_xll.ohRangeRetrieveError(D29)) | F29: =IF(WEEKDAY(A29,2)>5,"",_xll.qlIndexFixing(INDEX($B$14:$B$22,MATCH(B29,$A$14:$A$22,0)),A29,FALSE,D29)) -> -0.00363 | G29: =IF(WEEKDAY(A29,2)>5,"",F29-C29) -> 0
A31: Trigger (indexes and fixings ready) | B31: =AND(COUNTIF(D26:D29,TRUE)=3,SUMPRODUCT(--(C14:C20<>""))=0,C22="",C23="") -> TRUE

Sheet USD-FedFunds
A1: USD-FedFunds: Discount/LogLinear, A365, extrapolation; deposit 1D, OIS 1W-1Y (USD-OIS), average OIS 2Y-30Y (USD-AVERAGE-OIS)
A2: Average OIS: FedFunds compounded 3M + spread vs 6M 30/360 fixed (US calendar, MF), spot lag 2D, rate cutoff 2. Quote = 3M LIBOR swap rate, spread = 3M/1D basis.
A4: Segment | B4: Quote | C4: Rate | D4: Spread | E4: Helper | F4: Error
A5: Deposit | B5: MM/RATE/USD/0D/1D | C5: =MarketData!$E$126 -> USD-FedFunds_MM_RATE_USD_0D_1D#0000 | E5: =_xll.qlDepositRateHelper2("FF_DEP_1D",C5,"1D",0,"UnitedStates::FederalReserve","Following",FALSE,"Actual/360",FALSE,Indexes!$B$31) -> FF_DEP_1D#0000 | F5: =_xll.ohRangeRetrieveError(E5)
A6: OIS | B6: IR_SWAP/RATE/USD/2D/1D/1W | C6: =MarketData!$E$127 -> USD-FedFunds_IR_SWAP_RATE_USD_2D_1D_1W#0000 | E6: =_xll.qlQxOISRateHelper("FF_OIS_1W",2,"1W",C6,Indexes!$B$14,"Actual/360","UnitedStates::FederalReserve",2,"Annual","Following","Following","Backward","",TRUE,FALSE,FALSE,Indexes!$B$31) -> FF_OIS_1W#0000 | F6: =_xll.ohRangeRetrieveError(E6)
A7: OIS | B7: IR_SWAP/RATE/USD/2D/1D/2W | C7: =MarketData!$E$128 -> USD-FedFunds_IR_SWAP_RATE_USD_2D_1D_2W#0000 | E7: =_xll.qlQxOISRateHelper("FF_OIS_2W",2,"2W",C7,Indexes!$B$14,"Actual/360","UnitedStates::FederalReserve",2,"Annual","Following","Following","Backward","",TRUE,FALSE,FALSE,Indexes!$B$31) -> FF_OIS_2W#0000 | F7: =_xll.ohRangeRetrieveError(E7)
A8: OIS | B8: IR_SWAP/RATE/USD/2D/1D/3W | C8: =MarketData!$E$129 -> USD-FedFunds_IR_SWAP_RATE_USD_2D_1D_3W#0000 | E8: =_xll.qlQxOISRateHelper("FF_OIS_3W",2,"3W",C8,Indexes!$B$14,"Actual/360","UnitedStates::FederalReserve",2,"Annual","Following","Following","Backward","",TRUE,FALSE,FALSE,Indexes!$B$31) -> FF_OIS_3W#0000 | F8: =_xll.ohRangeRetrieveError(E8)
A9: OIS | B9: IR_SWAP/RATE/USD/2D/1D/1M | C9: =MarketData!$E$130 -> USD-FedFunds_IR_SWAP_RATE_USD_2D_1D_1M#0000 | E9: =_xll.qlQxOISRateHelper("FF_OIS_1M",2,"1M",C9,Indexes!$B$14,"Actual/360","UnitedStates::FederalReserve",2,"Annual","Following","Following","Backward","",TRUE,FALSE,FALSE,Indexes!$B$31) -> FF_OIS_1M#0000 | F9: =_xll.ohRangeRetrieveError(E9)
A10: OIS | B10: IR_SWAP/RATE/USD/2D/1D/2M | C10: =MarketData!$E$131 -> USD-FedFunds_IR_SWAP_RATE_USD_2D_1D_2M#0000 | E10: =_xll.qlQxOISRateHelper("FF_OIS_2M",2,"2M",C10,Indexes!$B$14,"Actual/360","UnitedStates::FederalReserve",2,"Annual","Following","Following","Backward","",TRUE,FALSE,FALSE,Indexes!$B$31) -> FF_OIS_2M#0000 | F10: =_xll.ohRangeRetrieveError(E10)
A11: OIS | B11: IR_SWAP/RATE/USD/2D/1D/3M | C11: =MarketData!$E$132 -> USD-FedFunds_IR_SWAP_RATE_USD_2D_1D_3M#0000 | E11: =_xll.qlQxOISRateHelper("FF_OIS_3M",2,"3M",C11,Indexes!$B$14,"Actual/360","UnitedStates::FederalReserve",2,"Annual","Following","Following","Backward","",TRUE,FALSE,FALSE,Indexes!$B$31) -> FF_OIS_3M#0000 | F11: =_xll.ohRangeRetrieveError(E11)
A12: OIS | B12: IR_SWAP/RATE/USD/2D/1D/4M | C12: =MarketData!$E$133 -> USD-FedFunds_IR_SWAP_RATE_USD_2D_1D_4M#0000 | E12: =_xll.qlQxOISRateHelper("FF_OIS_4M",2,"4M",C12,Indexes!$B$14,"Actual/360","UnitedStates::FederalReserve",2,"Annual","Following","Following","Backward","",TRUE,FALSE,FALSE,Indexes!$B$31) -> FF_OIS_4M#0000 | F12: =_xll.ohRangeRetrieveError(E12)
A13: OIS | B13: IR_SWAP/RATE/USD/2D/1D/5M | C13: =MarketData!$E$134 -> USD-FedFunds_IR_SWAP_RATE_USD_2D_1D_5M#0000 | E13: =_xll.qlQxOISRateHelper("FF_OIS_5M",2,"5M",C13,Indexes!$B$14,"Actual/360","UnitedStates::FederalReserve",2,"Annual","Following","Following","Backward","",TRUE,FALSE,FALSE,Indexes!$B$31) -> FF_OIS_5M#0000 | F13: =_xll.ohRangeRetrieveError(E13)
A14: OIS | B14: IR_SWAP/RATE/USD/2D/1D/6M | C14: =MarketData!$E$135 -> USD-FedFunds_IR_SWAP_RATE_USD_2D_1D_6M#0000 | E14: =_xll.qlQxOISRateHelper("FF_OIS_6M",2,"6M",C14,Indexes!$B$14,"Actual/360","UnitedStates::FederalReserve",2,"Annual","Following","Following","Backward","",TRUE,FALSE,FALSE,Indexes!$B$31) -> FF_OIS_6M#0000 | F14: =_xll.ohRangeRetrieveError(E14)
A15: OIS | B15: IR_SWAP/RATE/USD/2D/1D/7M | C15: =MarketData!$E$136 -> USD-FedFunds_IR_SWAP_RATE_USD_2D_1D_7M#0000 | E15: =_xll.qlQxOISRateHelper("FF_OIS_7M",2,"7M",C15,Indexes!$B$14,"Actual/360","UnitedStates::FederalReserve",2,"Annual","Following","Following","Backward","",TRUE,FALSE,FALSE,Indexes!$B$31) -> FF_OIS_7M#0000 | F15: =_xll.ohRangeRetrieveError(E15)
A16: OIS | B16: IR_SWAP/RATE/USD/2D/1D/8M | C16: =MarketData!$E$137 -> USD-FedFunds_IR_SWAP_RATE_USD_2D_1D_8M#0000 | E16: =_xll.qlQxOISRateHelper("FF_OIS_8M",2,"8M",C16,Indexes!$B$14,"Actual/360","UnitedStates::FederalReserve",2,"Annual","Following","Following","Backward","",TRUE,FALSE,FALSE,Indexes!$B$31) -> FF_OIS_8M#0000 | F16: =_xll.ohRangeRetrieveError(E16)
A17: OIS | B17: IR_SWAP/RATE/USD/2D/1D/9M | C17: =MarketData!$E$138 -> USD-FedFunds_IR_SWAP_RATE_USD_2D_1D_9M#0000 | E17: =_xll.qlQxOISRateHelper("FF_OIS_9M",2,"9M",C17,Indexes!$B$14,"Actual/360","UnitedStates::FederalReserve",2,"Annual","Following","Following","Backward","",TRUE,FALSE,FALSE,Indexes!$B$31) -> FF_OIS_9M#0000 | F17: =_xll.ohRangeRetrieveError(E17)
A18: OIS | B18: IR_SWAP/RATE/USD/2D/1D/10M | C18: =MarketData!$E$139 -> USD-FedFunds_IR_SWAP_RATE_USD_2D_1D_10M#0000 | E18: =_xll.qlQxOISRateHelper("FF_OIS_10M",2,"10M",C18,Indexes!$B$14,"Actual/360","UnitedStates::FederalReserve",2,"Annual","Following","Following","Backward","",TRUE,FALSE,FALSE,Indexes!$B$31) -> FF_OIS_10M#0000 | F18: =_xll.ohRangeRetrieveError(E18)
A19: OIS | B19: IR_SWAP/RATE/USD/2D/1D/11M | C19: =MarketData!$E$140 -> USD-FedFunds_IR_SWAP_RATE_USD_2D_1D_11M#0000 | E19: =_xll.qlQxOISRateHelper("FF_OIS_11M",2,"11M",C19,Indexes!$B$14,"Actual/360","UnitedStates::FederalReserve",2,"Annual","Following","Following","Backward","",TRUE,FALSE,FALSE,Indexes!$B$31) -> FF_OIS_11M#0000 | F19: =_xll.ohRangeRetrieveError(E19)
A20: OIS | B20: IR_SWAP/RATE/USD/2D/1D/1Y | C20: =MarketData!$E$141 -> USD-FedFunds_IR_SWAP_RATE_USD_2D_1D_1Y#0000 | E20: =_xll.qlQxOISRateHelper("FF_OIS_1Y",2,"1Y",C20,Indexes!$B$14,"Actual/360","UnitedStates::FederalReserve",2,"Annual","Following","Following","Backward","",TRUE,FALSE,FALSE,Indexes!$B$31) -> FF_OIS_1Y#0000 | F20: =_xll.ohRangeRetrieveError(E20)
A21: Average OIS | B21: IR_SWAP/RATE/USD/2D/3M/2Y + BASIS_SWAP/BASIS_SPREAD/3M/1D/USD/2Y | C21: =MarketData!$E$143 -> USD-FedFunds_IR_SWAP_RATE_USD_2D_3M_2Y#0000 | D21: =MarketData!$E$142 -> USD-FedFunds_BASIS_SWAP_BASIS_SPREAD_3M_1D_USD_2Y#0000 | E21: =_xll.qlAverageOISRateHelper("FF_AVGOIS_2Y",C21,"2D","2Y","6M","30/360","UnitedStates::Settlement","Modified Following","Modified Following",Indexes!$B$14,"3M",D21,2,"",FALSE,FALSE,Indexes!$B$31) -> FF_AVGOIS_2Y#0000 | F21: =_xll.ohRangeRetrieveError(E21)
A22: Average OIS | B22: IR_SWAP/RATE/USD/2D/3M/3Y + BASIS_SWAP/BASIS_SPREAD/3M/1D/USD/3Y | C22: =MarketData!$E$145 -> USD-FedFunds_IR_SWAP_RATE_USD_2D_3M_3Y#0000 | D22: =MarketData!$E$144 -> USD-FedFunds_BASIS_SWAP_BASIS_SPREAD_3M_1D_USD_3Y#0000 | E22: =_xll.qlAverageOISRateHelper("FF_AVGOIS_3Y",C22,"2D","3Y","6M","30/360","UnitedStates::Settlement","Modified Following","Modified Following",Indexes!$B$14,"3M",D22,2,"",FALSE,FALSE,Indexes!$B$31) -> FF_AVGOIS_3Y#0000 | F22: =_xll.ohRangeRetrieveError(E22)
A23: Average OIS | B23: IR_SWAP/RATE/USD/2D/3M/4Y + BASIS_SWAP/BASIS_SPREAD/3M/1D/USD/4Y | C23: =MarketData!$E$147 -> USD-FedFunds_IR_SWAP_RATE_USD_2D_3M_4Y#0000 | D23: =MarketData!$E$146 -> USD-FedFunds_BASIS_SWAP_BASIS_SPREAD_3M_1D_USD_4Y#0000 | E23: =_xll.qlAverageOISRateHelper("FF_AVGOIS_4Y",C23,"2D","4Y","6M","30/360","UnitedStates::Settlement","Modified Following","Modified Following",Indexes!$B$14,"3M",D23,2,"",FALSE,FALSE,Indexes!$B$31) -> FF_AVGOIS_4Y#0000 | F23: =_xll.ohRangeRetrieveError(E23)
A24: Average OIS | B24: IR_SWAP/RATE/USD/2D/3M/5Y + BASIS_SWAP/BASIS_SPREAD/3M/1D/USD/5Y | C24: =MarketData!$E$149 -> USD-FedFunds_IR_SWAP_RATE_USD_2D_3M_5Y#0000 | D24: =MarketData!$E$148 -> USD-FedFunds_BASIS_SWAP_BASIS_SPREAD_3M_1D_USD_5Y#0000 | E24: =_xll.qlAverageOISRateHelper("FF_AVGOIS_5Y",C24,"2D","5Y","6M","30/360","UnitedStates::Settlement","Modified Following","Modified Following",Indexes!$B$14,"3M",D24,2,"",FALSE,FALSE,Indexes!$B$31) -> FF_AVGOIS_5Y#0000 | F24: =_xll.ohRangeRetrieveError(E24)
A25: Average OIS | B25: IR_SWAP/RATE/USD/2D/3M/7Y + BASIS_SWAP/BASIS_SPREAD/3M/1D/USD/7Y | C25: =MarketData!$E$151 -> USD-FedFunds_IR_SWAP_RATE_USD_2D_3M_7Y#0000 | D25: =MarketData!$E$150 -> USD-FedFunds_BASIS_SWAP_BASIS_SPREAD_3M_1D_USD_7Y#0000 | E25: =_xll.qlAverageOISRateHelper("FF_AVGOIS_7Y",C25,"2D","7Y","6M","30/360","UnitedStates::Settlement","Modified Following","Modified Following",Indexes!$B$14,"3M",D25,2,"",FALSE,FALSE,Indexes!$B$31) -> FF_AVGOIS_7Y#0000 | F25: =_xll.ohRangeRetrieveError(E25)
A26: Average OIS | B26: IR_SWAP/RATE/USD/2D/3M/10Y + BASIS_SWAP/BASIS_SPREAD/3M/1D/USD/10Y | C26: =MarketData!$E$153 -> USD-FedFunds_IR_SWAP_RATE_USD_2D_3M_10Y#0000 | D26: =MarketData!$E$152 -> USD-FedFunds_BASIS_SWAP_BASIS_SPREAD_3M_1D_USD_10Y#0000 | E26: =_xll.qlAverageOISRateHelper("FF_AVGOIS_10Y",C26,"2D","10Y","6M","30/360","UnitedStates::Settlement","Modified Following","Modified Following",Indexes!$B$14,"3M",D26,2,"",FALSE,FALSE,Indexes!$B$31) -> FF_AVGOIS_10Y#0000 | F26: =_xll.ohRangeRetrieveError(E26)
A27: Average OIS | B27: IR_SWAP/RATE/USD/2D/3M/15Y + BASIS_SWAP/BASIS_SPREAD/3M/1D/USD/15Y | C27: =MarketData!$E$155 -> USD-FedFunds_IR_SWAP_RATE_USD_2D_3M_15Y#0000 | D27: =MarketData!$E$154 -> USD-FedFunds_BASIS_SWAP_BASIS_SPREAD_3M_1D_USD_15Y#0000 | E27: =_xll.qlAverageOISRateHelper("FF_AVGOIS_15Y",C27,"2D","15Y","6M","30/360","UnitedStates::Settlement","Modified Following","Modified Following",Indexes!$B$14,"3M",D27,2,"",FALSE,FALSE,Indexes!$B$31) -> FF_AVGOIS_15Y#0000 | F27: =_xll.ohRangeRetrieveError(E27)
A28: Average OIS | B28: IR_SWAP/RATE/USD/2D/3M/20Y + BASIS_SWAP/BASIS_SPREAD/3M/1D/USD/20Y | C28: =MarketData!$E$157 -> USD-FedFunds_IR_SWAP_RATE_USD_2D_3M_20Y#0000 | D28: =MarketData!$E$156 -> USD-FedFunds_BASIS_SWAP_BASIS_SPREAD_3M_1D_USD_20Y#0000 | E28: =_xll.qlAverageOISRateHelper("FF_AVGOIS_20Y",C28,"2D","20Y","6M","30/360","UnitedStates::Settlement","Modified Following","Modified Following",Indexes!$B$14,"3M",D28,2,"",FALSE,FALSE,Indexes!$B$31) -> FF_AVGOIS_20Y#0000 | F28: =_xll.ohRangeRetrieveError(E28)
A29: Average OIS | B29: IR_SWAP/RATE/USD/2D/3M/30Y + BASIS_SWAP/BASIS_SPREAD/3M/1D/USD/30Y | C29: =MarketData!$E$159 -> USD-FedFunds_IR_SWAP_RATE_USD_2D_3M_30Y#0000 | D29: =MarketData!$E$158 -> USD-FedFunds_BASIS_SWAP_BASIS_SPREAD_3M_1D_USD_30Y#0000 | E29: =_xll.qlAverageOISRateHelper("FF_AVGOIS_30Y",C29,"2D","30Y","6M","30/360","UnitedStates::Settlement","Modified Following","Modified Following",Indexes!$B$14,"3M",D29,2,"",FALSE,FALSE,Indexes!$B$31) -> FF_AVGOIS_30Y#0000 | F29: =_xll.ohRangeRetrieveError(E29)
A31: Curve | B31: =_xll.qlPiecewiseYieldCurve("C_USD-FedFunds",0,"UnitedStates::FederalReserve",E5:E29,"Actual/365 (Fixed)",,,"Discount","LogLinear",FALSE,Indexes!$B$31) -> C_USD-FedFunds#0000 | C31: =_xll.ohRangeRetrieveError(B31) | D31: =_xll.qlExtrapolatorEnableExtrapolation(B31,TRUE) -> TRUE
A32: Link handle H_USD-FedFunds | B32: =_xll.qlRelinkableHandleLinkTo(Indexes!$B$5,B31,D31) -> TRUE | C32: =_xll.ohRangeRetrieveError(B32)
A34: Date | B34: ORE discount factor | C34: Excel discount factor | D34: Difference | E34: Rel. difference
A35: =DATE(2019,12,31) -> 43830 | B35: 0.99995695 | C35: =_xll.qlYieldTSDiscount($B$31,A35,TRUE,$B$32) -> 0.99995695 | D35: =C35-B35 -> 0 | E35: =D35/B35 -> 0
A36: =DATE(2020,1,13) -> 43843 | B36: 0.99939864 | C36: =_xll.qlYieldTSDiscount($B$31,A36,TRUE,$B$32) -> 0.99939864 | D36: =C36-B36 -> 0 | E36: =D36/B36 -> 0
A37: =DATE(2020,1,21) -> 43851 | B37: 0.99905298 | C37: =_xll.qlYieldTSDiscount($B$31,A37,TRUE,$B$32) -> 0.99905298 | D37: =C37-B37 -> 0 | E37: =D37/B37 -> 0
A38: =DATE(2020,1,27) -> 43857 | B38: 0.99879972 | C38: =_xll.qlYieldTSDiscount($B$31,A38,TRUE,$B$32) -> 0.99879972 | D38: =C38-B38 -> 0 | E38: =D38/B38 -> 0
A39: =DATE(2020,2,5) -> 43866 | B39: 0.9984045 | C39: =_xll.qlYieldTSDiscount($B$31,A39,TRUE,$B$32) -> 0.9984045 | D39: =C39-B39 -> 0 | E39: =D39/B39 -> 0
A40: =DATE(2020,3,4) -> 43894 | B40: 0.99719027 | C40: =_xll.qlYieldTSDiscount($B$31,A40,TRUE,$B$32) -> 0.99719027 | D40: =C40-B40 -> 0 | E40: =D40/B40 -> 0
A41: =DATE(2020,4,6) -> 43927 | B41: 0.9957676 | C41: =_xll.qlYieldTSDiscount($B$31,A41,TRUE,$B$32) -> 0.9957676 | D41: =C41-B41 -> 0 | E41: =D41/B41 -> 0
A42: =DATE(2020,5,6) -> 43957 | B42: 0.99448666 | C42: =_xll.qlYieldTSDiscount($B$31,A42,TRUE,$B$32) -> 0.99448666 | D42: =C42-B42 -> 0 | E42: =D42/B42 -> 0
A43: =DATE(2020,6,4) -> 43986 | B43: 0.99325778 | C43: =_xll.qlYieldTSDiscount($B$31,A43,TRUE,$B$32) -> 0.99325778 | D43: =C43-B43 -> 0 | E43: =D43/B43 -> 0
...

Sheet EUR-EONIA
A1: EUR-EONIA: Discount/LogLinear, A365, extrapolation; deposit 1D (EUR-ON-DEPOSIT), OIS 1W-30Y (EUR-OIS)
A2: EUR-OIS: spot lag 2, fixed A360, TARGET, payment lag 1, Annual, Following/Following, Backward, EOM false.
A4: Segment | B4: Quote | C4: Rate | E4: Helper | F4: Error
A5: Deposit | B5: MM/RATE/EUR/0D/1D | C5: =MarketData!$E$7 -> EUR-EONIA_MM_RATE_EUR_0D_1D#0000 | E5: =_xll.qlDepositRateHelper2("EONIA_DEP_1D",C5,"1D",0,"TARGET","Following",FALSE,"Actual/360",FALSE,Indexes!$B$31) -> EONIA_DEP_1D#0000 | F5: =_xll.ohRangeRetrieveError(E5)
A6: OIS | B6: IR_SWAP/RATE/EUR/2D/1D/1W | C6: =MarketData!$E$8 -> EUR-EONIA_IR_SWAP_RATE_EUR_2D_1D_1W#0000 | E6: =_xll.qlQxOISRateHelper("EONIA_OIS_1W",2,"1W",C6,Indexes!$B$15,"Actual/360","TARGET",1,"Annual","Following","Following","Backward","",TRUE,FALSE,FALSE,Indexes!$B$31) -> EONIA_OIS_1W#0000 | F6: =_xll.ohRangeRetrieveError(E6)
A7: OIS | B7: IR_SWAP/RATE/EUR/2D/1D/2W | C7: =MarketData!$E$9 -> EUR-EONIA_IR_SWAP_RATE_EUR_2D_1D_2W#0000 | E7: =_xll.qlQxOISRateHelper("EONIA_OIS_2W",2,"2W",C7,Indexes!$B$15,"Actual/360","TARGET",1,"Annual","Following","Following","Backward","",TRUE,FALSE,FALSE,Indexes!$B$31) -> EONIA_OIS_2W#0000 | F7: =_xll.ohRangeRetrieveError(E7)
A8: OIS | B8: IR_SWAP/RATE/EUR/2D/1D/3W | C8: =MarketData!$E$10 -> EUR-EONIA_IR_SWAP_RATE_EUR_2D_1D_3W#0000 | E8: =_xll.qlQxOISRateHelper("EONIA_OIS_3W",2,"3W",C8,Indexes!$B$15,"Actual/360","TARGET",1,"Annual","Following","Following","Backward","",TRUE,FALSE,FALSE,Indexes!$B$31) -> EONIA_OIS_3W#0000 | F8: =_xll.ohRangeRetrieveError(E8)
A9: OIS | B9: IR_SWAP/RATE/EUR/2D/1D/1M | C9: =MarketData!$E$11 -> EUR-EONIA_IR_SWAP_RATE_EUR_2D_1D_1M#0000 | E9: =_xll.qlQxOISRateHelper("EONIA_OIS_1M",2,"1M",C9,Indexes!$B$15,"Actual/360","TARGET",1,"Annual","Following","Following","Backward","",TRUE,FALSE,FALSE,Indexes!$B$31) -> EONIA_OIS_1M#0000 | F9: =_xll.ohRangeRetrieveError(E9)
A10: OIS | B10: IR_SWAP/RATE/EUR/2D/1D/2M | C10: =MarketData!$E$12 -> EUR-EONIA_IR_SWAP_RATE_EUR_2D_1D_2M#0000 | E10: =_xll.qlQxOISRateHelper("EONIA_OIS_2M",2,"2M",C10,Indexes!$B$15,"Actual/360","TARGET",1,"Annual","Following","Following","Backward","",TRUE,FALSE,FALSE,Indexes!$B$31) -> EONIA_OIS_2M#0000 | F10: =_xll.ohRangeRetrieveError(E10)
A11: OIS | B11: IR_SWAP/RATE/EUR/2D/1D/3M | C11: =MarketData!$E$13 -> EUR-EONIA_IR_SWAP_RATE_EUR_2D_1D_3M#0000 | E11: =_xll.qlQxOISRateHelper("EONIA_OIS_3M",2,"3M",C11,Indexes!$B$15,"Actual/360","TARGET",1,"Annual","Following","Following","Backward","",TRUE,FALSE,FALSE,Indexes!$B$31) -> EONIA_OIS_3M#0000 | F11: =_xll.ohRangeRetrieveError(E11)
A12: OIS | B12: IR_SWAP/RATE/EUR/2D/1D/4M | C12: =MarketData!$E$14 -> EUR-EONIA_IR_SWAP_RATE_EUR_2D_1D_4M#0000 | E12: =_xll.qlQxOISRateHelper("EONIA_OIS_4M",2,"4M",C12,Indexes!$B$15,"Actual/360","TARGET",1,"Annual","Following","Following","Backward","",TRUE,FALSE,FALSE,Indexes!$B$31) -> EONIA_OIS_4M#0000 | F12: =_xll.ohRangeRetrieveError(E12)
A13: OIS | B13: IR_SWAP/RATE/EUR/2D/1D/5M | C13: =MarketData!$E$15 -> EUR-EONIA_IR_SWAP_RATE_EUR_2D_1D_5M#0000 | E13: =_xll.qlQxOISRateHelper("EONIA_OIS_5M",2,"5M",C13,Indexes!$B$15,"Actual/360","TARGET",1,"Annual","Following","Following","Backward","",TRUE,FALSE,FALSE,Indexes!$B$31) -> EONIA_OIS_5M#0000 | F13: =_xll.ohRangeRetrieveError(E13)
A14: OIS | B14: IR_SWAP/RATE/EUR/2D/1D/6M | C14: =MarketData!$E$16 -> EUR-EONIA_IR_SWAP_RATE_EUR_2D_1D_6M#0000 | E14: =_xll.qlQxOISRateHelper("EONIA_OIS_6M",2,"6M",C14,Indexes!$B$15,"Actual/360","TARGET",1,"Annual","Following","Following","Backward","",TRUE,FALSE,FALSE,Indexes!$B$31) -> EONIA_OIS_6M#0000 | F14: =_xll.ohRangeRetrieveError(E14)
A15: OIS | B15: IR_SWAP/RATE/EUR/2D/1D/7M | C15: =MarketData!$E$17 -> EUR-EONIA_IR_SWAP_RATE_EUR_2D_1D_7M#0000 | E15: =_xll.qlQxOISRateHelper("EONIA_OIS_7M",2,"7M",C15,Indexes!$B$15,"Actual/360","TARGET",1,"Annual","Following","Following","Backward","",TRUE,FALSE,FALSE,Indexes!$B$31) -> EONIA_OIS_7M#0000 | F15: =_xll.ohRangeRetrieveError(E15)
A16: OIS | B16: IR_SWAP/RATE/EUR/2D/1D/8M | C16: =MarketData!$E$18 -> EUR-EONIA_IR_SWAP_RATE_EUR_2D_1D_8M#0000 | E16: =_xll.qlQxOISRateHelper("EONIA_OIS_8M",2,"8M",C16,Indexes!$B$15,"Actual/360","TARGET",1,"Annual","Following","Following","Backward","",TRUE,FALSE,FALSE,Indexes!$B$31) -> EONIA_OIS_8M#0000 | F16: =_xll.ohRangeRetrieveError(E16)
A17: OIS | B17: IR_SWAP/RATE/EUR/2D/1D/9M | C17: =MarketData!$E$19 -> EUR-EONIA_IR_SWAP_RATE_EUR_2D_1D_9M#0000 | E17: =_xll.qlQxOISRateHelper("EONIA_OIS_9M",2,"9M",C17,Indexes!$B$15,"Actual/360","TARGET",1,"Annual","Following","Following","Backward","",TRUE,FALSE,FALSE,Indexes!$B$31) -> EONIA_OIS_9M#0000 | F17: =_xll.ohRangeRetrieveError(E17)
A18: OIS | B18: IR_SWAP/RATE/EUR/2D/1D/10M | C18: =MarketData!$E$20 -> EUR-EONIA_IR_SWAP_RATE_EUR_2D_1D_10M#0000 | E18: =_xll.qlQxOISRateHelper("EONIA_OIS_10M",2,"10M",C18,Indexes!$B$15,"Actual/360","TARGET",1,"Annual","Following","Following","Backward","",TRUE,FALSE,FALSE,Indexes!$B$31) -> EONIA_OIS_10M#0000 | F18: =_xll.ohRangeRetrieveError(E18)
A19: OIS | B19: IR_SWAP/RATE/EUR/2D/1D/11M | C19: =MarketData!$E$21 -> EUR-EONIA_IR_SWAP_RATE_EUR_2D_1D_11M#0000 | E19: =_xll.qlQxOISRateHelper("EONIA_OIS_11M",2,"11M",C19,Indexes!$B$15,"Actual/360","TARGET",1,"Annual","Following","Following","Backward","",TRUE,FALSE,FALSE,Indexes!$B$31) -> EONIA_OIS_11M#0000 | F19: =_xll.ohRangeRetrieveError(E19)
A20: OIS | B20: IR_SWAP/RATE/EUR/2D/1D/1Y | C20: =MarketData!$E$22 -> EUR-EONIA_IR_SWAP_RATE_EUR_2D_1D_1Y#0000 | E20: =_xll.qlQxOISRateHelper("EONIA_OIS_1Y",2,"1Y",C20,Indexes!$B$15,"Actual/360","TARGET",1,"Annual","Following","Following","Backward","",TRUE,FALSE,FALSE,Indexes!$B$31) -> EONIA_OIS_1Y#0000 | F20: =_xll.ohRangeRetrieveError(E20)
A21: OIS | B21: IR_SWAP/RATE/EUR/2D/1D/15M | C21: =MarketData!$E$23 -> EUR-EONIA_IR_SWAP_RATE_EUR_2D_1D_15M#0000 | E21: =_xll.qlQxOISRateHelper("EONIA_OIS_15M",2,"15M",C21,Indexes!$B$15,"Actual/360","TARGET",1,"Annual","Following","Following","Backward","",TRUE,FALSE,FALSE,Indexes!$B$31) -> EONIA_OIS_15M#0000 | F21: =_xll.ohRangeRetrieveError(E21)
A22: OIS | B22: IR_SWAP/RATE/EUR/2D/1D/18M | C22: =MarketData!$E$24 -> EUR-EONIA_IR_SWAP_RATE_EUR_2D_1D_18M#0000 | E22: =_xll.qlQxOISRateHelper("EONIA_OIS_18M",2,"18M",C22,Indexes!$B$15,"Actual/360","TARGET",1,"Annual","Following","Following","Backward","",TRUE,FALSE,FALSE,Indexes!$B$31) -> EONIA_OIS_18M#0000 | F22: =_xll.ohRangeRetrieveError(E22)
A23: OIS | B23: IR_SWAP/RATE/EUR/2D/1D/21M | C23: =MarketData!$E$25 -> EUR-EONIA_IR_SWAP_RATE_EUR_2D_1D_21M#0000 | E23: =_xll.qlQxOISRateHelper("EONIA_OIS_21M",2,"21M",C23,Indexes!$B$15,"Actual/360","TARGET",1,"Annual","Following","Following","Backward","",TRUE,FALSE,FALSE,Indexes!$B$31) -> EONIA_OIS_21M#0000 | F23: =_xll.ohRangeRetrieveError(E23)
A24: OIS | B24: IR_SWAP/RATE/EUR/2D/1D/2Y | C24: =MarketData!$E$26 -> EUR-EONIA_IR_SWAP_RATE_EUR_2D_1D_2Y#0000 | E24: =_xll.qlQxOISRateHelper("EONIA_OIS_2Y",2,"2Y",C24,Indexes!$B$15,"Actual/360","TARGET",1,"Annual","Following","Following","Backward","",TRUE,FALSE,FALSE,Indexes!$B$31) -> EONIA_OIS_2Y#0000 | F24: =_xll.ohRangeRetrieveError(E24)
A25: OIS | B25: IR_SWAP/RATE/EUR/2D/1D/3Y | C25: =MarketData!$E$27 -> EUR-EONIA_IR_SWAP_RATE_EUR_2D_1D_3Y#0000 | E25: =_xll.qlQxOISRateHelper("EONIA_OIS_3Y",2,"3Y",C25,Indexes!$B$15,"Actual/360","TARGET",1,"Annual","Following","Following","Backward","",TRUE,FALSE,FALSE,Indexes!$B$31) -> EONIA_OIS_3Y#0000 | F25: =_xll.ohRangeRetrieveError(E25)
A26: OIS | B26: IR_SWAP/RATE/EUR/2D/1D/4Y | C26: =MarketData!$E$28 -> EUR-EONIA_IR_SWAP_RATE_EUR_2D_1D_4Y#0000 | E26: =_xll.qlQxOISRateHelper("EONIA_OIS_4Y",2,"4Y",C26,Indexes!$B$15,"Actual/360","TARGET",1,"Annual","Following","Following","Backward","",TRUE,FALSE,FALSE,Indexes!$B$31) -> EONIA_OIS_4Y#0000 | F26: =_xll.ohRangeRetrieveError(E26)
A27: OIS | B27: IR_SWAP/RATE/EUR/2D/1D/5Y | C27: =MarketData!$E$29 -> EUR-EONIA_IR_SWAP_RATE_EUR_2D_1D_5Y#0000 | E27: =_xll.qlQxOISRateHelper("EONIA_OIS_5Y",2,"5Y",C27,Indexes!$B$15,"Actual/360","TARGET",1,"Annual","Following","Following","Backward","",TRUE,FALSE,FALSE,Indexes!$B$31) -> EONIA_OIS_5Y#0000 | F27: =_xll.ohRangeRetrieveError(E27)
A28: OIS | B28: IR_SWAP/RATE/EUR/2D/1D/6Y | C28: =MarketData!$E$30 -> EUR-EONIA_IR_SWAP_RATE_EUR_2D_1D_6Y#0000 | E28: =_xll.qlQxOISRateHelper("EONIA_OIS_6Y",2,"6Y",C28,Indexes!$B$15,"Actual/360","TARGET",1,"Annual","Following","Following","Backward","",TRUE,FALSE,FALSE,Indexes!$B$31) -> EONIA_OIS_6Y#0000 | F28: =_xll.ohRangeRetrieveError(E28)
A29: OIS | B29: IR_SWAP/RATE/EUR/2D/1D/7Y | C29: =MarketData!$E$31 -> EUR-EONIA_IR_SWAP_RATE_EUR_2D_1D_7Y#0000 | E29: =_xll.qlQxOISRateHelper("EONIA_OIS_7Y",2,"7Y",C29,Indexes!$B$15,"Actual/360","TARGET",1,"Annual","Following","Following","Backward","",TRUE,FALSE,FALSE,Indexes!$B$31) -> EONIA_OIS_7Y#0000 | F29: =_xll.ohRangeRetrieveError(E29)
A30: OIS | B30: IR_SWAP/RATE/EUR/2D/1D/8Y | C30: =MarketData!$E$32 -> EUR-EONIA_IR_SWAP_RATE_EUR_2D_1D_8Y#0000 | E30: =_xll.qlQxOISRateHelper("EONIA_OIS_8Y",2,"8Y",C30,Indexes!$B$15,"Actual/360","TARGET",1,"Annual","Following","Following","Backward","",TRUE,FALSE,FALSE,Indexes!$B$31) -> EONIA_OIS_8Y#0000 | F30: =_xll.ohRangeRetrieveError(E30)
A31: OIS | B31: IR_SWAP/RATE/EUR/2D/1D/9Y | C31: =MarketData!$E$33 -> EUR-EONIA_IR_SWAP_RATE_EUR_2D_1D_9Y#0000 | E31: =_xll.qlQxOISRateHelper("EONIA_OIS_9Y",2,"9Y",C31,Indexes!$B$15,"Actual/360","TARGET",1,"Annual","Following","Following","Backward","",TRUE,FALSE,FALSE,Indexes!$B$31) -> EONIA_OIS_9Y#0000 | F31: =_xll.ohRangeRetrieveError(E31)
A32: OIS | B32: IR_SWAP/RATE/EUR/2D/1D/10Y | C32: =MarketData!$E$34 -> EUR-EONIA_IR_SWAP_RATE_EUR_2D_1D_10Y#0000 | E32: =_xll.qlQxOISRateHelper("EONIA_OIS_10Y",2,"10Y",C32,Indexes!$B$15,"Actual/360","TARGET",1,"Annual","Following","Following","Backward","",TRUE,FALSE,FALSE,Indexes!$B$31) -> EONIA_OIS_10Y#0000 | F32: =_xll.ohRangeRetrieveError(E32)
A33: OIS | B33: IR_SWAP/RATE/EUR/2D/1D/11Y | C33: =MarketData!$E$35 -> EUR-EONIA_IR_SWAP_RATE_EUR_2D_1D_11Y#0000 | E33: =_xll.qlQxOISRateHelper("EONIA_OIS_11Y",2,"11Y",C33,Indexes!$B$15,"Actual/360","TARGET",1,"Annual","Following","Following","Backward","",TRUE,FALSE,FALSE,Indexes!$B$31) -> EONIA_OIS_11Y#0000 | F33: =_xll.ohRangeRetrieveError(E33)
A34: OIS | B34: IR_SWAP/RATE/EUR/2D/1D/12Y | C34: =MarketData!$E$36 -> EUR-EONIA_IR_SWAP_RATE_EUR_2D_1D_12Y#0000 | E34: =_xll.qlQxOISRateHelper("EONIA_OIS_12Y",2,"12Y",C34,Indexes!$B$15,"Actual/360","TARGET",1,"Annual","Following","Following","Backward","",TRUE,FALSE,FALSE,Indexes!$B$31) -> EONIA_OIS_12Y#0000 | F34: =_xll.ohRangeRetrieveError(E34)
A35: OIS | B35: IR_SWAP/RATE/EUR/2D/1D/15Y | C35: =MarketData!$E$37 -> EUR-EONIA_IR_SWAP_RATE_EUR_2D_1D_15Y#0000 | E35: =_xll.qlQxOISRateHelper("EONIA_OIS_15Y",2,"15Y",C35,Indexes!$B$15,"Actual/360","TARGET",1,"Annual","Following","Following","Backward","",TRUE,FALSE,FALSE,Indexes!$B$31) -> EONIA_OIS_15Y#0000 | F35: =_xll.ohRangeRetrieveError(E35)
A36: OIS | B36: IR_SWAP/RATE/EUR/2D/1D/20Y | C36: =MarketData!$E$38 -> EUR-EONIA_IR_SWAP_RATE_EUR_2D_1D_20Y#0000 | E36: =_xll.qlQxOISRateHelper("EONIA_OIS_20Y",2,"20Y",C36,Indexes!$B$15,"Actual/360","TARGET",1,"Annual","Following","Following","Backward","",TRUE,FALSE,FALSE,Indexes!$B$31) -> EONIA_OIS_20Y#0000 | F36: =_xll.ohRangeRetrieveError(E36)
A37: OIS | B37: IR_SWAP/RATE/EUR/2D/1D/25Y | C37: =MarketData!$E$39 -> EUR-EONIA_IR_SWAP_RATE_EUR_2D_1D_25Y#0000 | E37: =_xll.qlQxOISRateHelper("EONIA_OIS_25Y",2,"25Y",C37,Indexes!$B$15,"Actual/360","TARGET",1,"Annual","Following","Following","Backward","",TRUE,FALSE,FALSE,Indexes!$B$31) -> EONIA_OIS_25Y#0000 | F37: =_xll.ohRangeRetrieveError(E37)
A38: OIS | B38: IR_SWAP/RATE/EUR/2D/1D/30Y | C38: =MarketData!$E$40 -> EUR-EONIA_IR_SWAP_RATE_EUR_2D_1D_30Y#0000 | E38: =_xll.qlQxOISRateHelper("EONIA_OIS_30Y",2,"30Y",C38,Indexes!$B$15,"Actual/360","TARGET",1,"Annual","Following","Following","Backward","",TRUE,FALSE,FALSE,Indexes!$B$31) -> EONIA_OIS_30Y#0000 | F38: =_xll.ohRangeRetrieveError(E38)
A40: Curve | B40: =_xll.qlPiecewiseYieldCurve("C_EUR-EONIA",0,"TARGET",E5:E38,"Actual/365 (Fixed)",,,"Discount","LogLinear",FALSE,Indexes!$B$31) -> C_EUR-EONIA#0000 | C40: =_xll.ohRangeRetrieveError(B40) | D40: =_xll.qlExtrapolatorEnableExtrapolation(B40,TRUE) -> TRUE
A41: Link handle H_EUR-EONIA | B41: =_xll.qlRelinkableHandleLinkTo(Indexes!$B$6,B40,D40) -> TRUE | C41: =_xll.ohRangeRetrieveError(B41)
A43: Date | B43: ORE discount factor | C43: Excel discount factor | D43: Difference | E43: Rel. difference
...

Sheet USD-LIBOR-3M
A1: USD-LIBOR-3M: Discount/LogLinear, A365, extrapolation; discount curve USD-FedFunds; deposit 3M, FRAs 1x4..9x12, swaps 2Y-50Y
A2: USD-LIBOR-3M-SWAP: fixed calendar US+UK, Semiannual, MF, 30/360 (USA); float index USD-LIBOR-3M.
A4: Segment | B4: Quote | C4: Rate | E4: Helper | F4: Error
A5: Deposit | B5: MM/RATE/USD/2D/3M | C5: =MarketData!$E$160 -> USD-LIBOR-3M_MM_RATE_USD_2D_3M#0000 | E5: =_xll.qlDepositRateHelper2("LIBOR3M_DEP",C5,"3M",2,"UnitedKingdom::Exchange","Modified Following",TRUE,"Actual/360",FALSE,Indexes!$B$31) -> LIBOR3M_DEP#0000 | F5: =_xll.ohRangeRetrieveError(E5)
A6: FRA | B6: FRA/RATE/USD/1M/3M | C6: =MarketData!$E$161 -> USD-LIBOR-3M_FRA_RATE_USD_1M_3M#0000 | E6: =_xll.qlFraRateHelper("LIBOR3M_FRA_1M",C6,"1M",Indexes!$B$16,"LastRelevantDate",,FALSE,Indexes!$B$31) -> LIBOR3M_FRA_1M#0000 | F6: =_xll.ohRangeRetrieveError(E6)
A7: FRA | B7: FRA/RATE/USD/2M/3M | C7: =MarketData!$E$162 -> USD-LIBOR-3M_FRA_RATE_USD_2M_3M#0000 | E7: =_xll.qlFraRateHelper("LIBOR3M_FRA_2M",C7,"2M",Indexes!$B$16,"LastRelevantDate",,FALSE,Indexes!$B$31) -> LIBOR3M_FRA_2M#0000 | F7: =_xll.ohRangeRetrieveError(E7)
A8: FRA | B8: FRA/RATE/USD/3M/3M | C8: =MarketData!$E$163 -> USD-LIBOR-3M_FRA_RATE_USD_3M_3M#0000 | E8: =_xll.qlFraRateHelper("LIBOR3M_FRA_3M",C8,"3M",Indexes!$B$16,"LastRelevantDate",,FALSE,Indexes!$B$31) -> LIBOR3M_FRA_3M#0000 | F8: =_xll.ohRangeRetrieveError(E8)
A9: FRA | B9: FRA/RATE/USD/4M/3M | C9: =MarketData!$E$164 -> USD-LIBOR-3M_FRA_RATE_USD_4M_3M#0000 | E9: =_xll.qlFraRateHelper("LIBOR3M_FRA_4M",C9,"4M",Indexes!$B$16,"LastRelevantDate",,FALSE,Indexes!$B$31) -> LIBOR3M_FRA_4M#0000 | F9: =_xll.ohRangeRetrieveError(E9)
A10: FRA | B10: FRA/RATE/USD/5M/3M | C10: =MarketData!$E$165 -> USD-LIBOR-3M_FRA_RATE_USD_5M_3M#0000 | E10: =_xll.qlFraRateHelper("LIBOR3M_FRA_5M",C10,"5M",Indexes!$B$16,"LastRelevantDate",,FALSE,Indexes!$B$31) -> LIBOR3M_FRA_5M#0000 | F10: =_xll.ohRangeRetrieveError(E10)
A11: FRA | B11: FRA/RATE/USD/6M/3M | C11: =MarketData!$E$166 -> USD-LIBOR-3M_FRA_RATE_USD_6M_3M#0000 | E11: =_xll.qlFraRateHelper("LIBOR3M_FRA_6M",C11,"6M",Indexes!$B$16,"LastRelevantDate",,FALSE,Indexes!$B$31) -> LIBOR3M_FRA_6M#0000 | F11: =_xll.ohRangeRetrieveError(E11)
A12: FRA | B12: FRA/RATE/USD/7M/3M | C12: =MarketData!$E$167 -> USD-LIBOR-3M_FRA_RATE_USD_7M_3M#0000 | E12: =_xll.qlFraRateHelper("LIBOR3M_FRA_7M",C12,"7M",Indexes!$B$16,"LastRelevantDate",,FALSE,Indexes!$B$31) -> LIBOR3M_FRA_7M#0000 | F12: =_xll.ohRangeRetrieveError(E12)
A13: FRA | B13: FRA/RATE/USD/8M/3M | C13: =MarketData!$E$168 -> USD-LIBOR-3M_FRA_RATE_USD_8M_3M#0000 | E13: =_xll.qlFraRateHelper("LIBOR3M_FRA_8M",C13,"8M",Indexes!$B$16,"LastRelevantDate",,FALSE,Indexes!$B$31) -> LIBOR3M_FRA_8M#0000 | F13: =_xll.ohRangeRetrieveError(E13)
A14: FRA | B14: FRA/RATE/USD/9M/3M | C14: =MarketData!$E$169 -> USD-LIBOR-3M_FRA_RATE_USD_9M_3M#0000 | E14: =_xll.qlFraRateHelper("LIBOR3M_FRA_9M",C14,"9M",Indexes!$B$16,"LastRelevantDate",,FALSE,Indexes!$B$31) -> LIBOR3M_FRA_9M#0000 | F14: =_xll.ohRangeRetrieveError(E14)
A15: Swap | B15: IR_SWAP/RATE/USD/2D/3M/2Y | C15: =MarketData!$E$170 -> USD-LIBOR-3M_IR_SWAP_RATE_USD_2D_3M_2Y#0000 | E15: =_xll.qlSwapRateHelper2("LIBOR3M_SWAP_2Y",C15,,"2Y","JoinHolidays(UnitedStates::Settlement,UnitedKingdom::Settlement)","Semiannual","Modified Following","30/360 (USA)",Indexes!$B$16,0,"0D",Indexes!$B$5,"LastRelevantDate",,FALSE,'USD-FedFunds'!$B$32) -> LIBOR3M_SWAP_2Y#0000 | F15: =_xll.ohRangeRetrieveError(E15)
A16: Swap | B16: IR_SWAP/RATE/USD/2D/3M/3Y | C16: =MarketData!$E$171 -> USD-LIBOR-3M_IR_SWAP_RATE_USD_2D_3M_3Y#0000 | E16: =_xll.qlSwapRateHelper2("LIBOR3M_SWAP_3Y",C16,,"3Y","JoinHolidays(UnitedStates::Settlement,UnitedKingdom::Settlement)","Semiannual","Modified Following","30/360 (USA)",Indexes!$B$16,0,"0D",Indexes!$B$5,"LastRelevantDate",,FALSE,'USD-FedFunds'!$B$32) -> LIBOR3M_SWAP_3Y#0000 | F16: =_xll.ohRangeRetrieveError(E16)
A17: Swap | B17: IR_SWAP/RATE/USD/2D/3M/4Y | C17: =MarketData!$E$172 -> USD-LIBOR-3M_IR_SWAP_RATE_USD_2D_3M_4Y#0000 | E17: =_xll.qlSwapRateHelper2("LIBOR3M_SWAP_4Y",C17,,"4Y","JoinHolidays(UnitedStates::Settlement,UnitedKingdom::Settlement)","Semiannual","Modified Following","30/360 (USA)",Indexes!$B$16,0,"0D",Indexes!$B$5,"LastRelevantDate",,FALSE,'USD-FedFunds'!$B$32) -> LIBOR3M_SWAP_4Y#0000 | F17: =_xll.ohRangeRetrieveError(E17)
A18: Swap | B18: IR_SWAP/RATE/USD/2D/3M/5Y | C18: =MarketData!$E$173 -> USD-LIBOR-3M_IR_SWAP_RATE_USD_2D_3M_5Y#0000 | E18: =_xll.qlSwapRateHelper2("LIBOR3M_SWAP_5Y",C18,,"5Y","JoinHolidays(UnitedStates::Settlement,UnitedKingdom::Settlement)","Semiannual","Modified Following","30/360 (USA)",Indexes!$B$16,0,"0D",Indexes!$B$5,"LastRelevantDate",,FALSE,'USD-FedFunds'!$B$32) -> LIBOR3M_SWAP_5Y#0000 | F18: =_xll.ohRangeRetrieveError(E18)
A19: Swap | B19: IR_SWAP/RATE/USD/2D/3M/6Y | C19: =MarketData!$E$174 -> USD-LIBOR-3M_IR_SWAP_RATE_USD_2D_3M_6Y#0000 | E19: =_xll.qlSwapRateHelper2("LIBOR3M_SWAP_6Y",C19,,"6Y","JoinHolidays(UnitedStates::Settlement,UnitedKingdom::Settlement)","Semiannual","Modified Following","30/360 (USA)",Indexes!$B$16,0,"0D",Indexes!$B$5,"LastRelevantDate",,FALSE,'USD-FedFunds'!$B$32) -> LIBOR3M_SWAP_6Y#0000 | F19: =_xll.ohRangeRetrieveError(E19)
A20: Swap | B20: IR_SWAP/RATE/USD/2D/3M/7Y | C20: =MarketData!$E$175 -> USD-LIBOR-3M_IR_SWAP_RATE_USD_2D_3M_7Y#0000 | E20: =_xll.qlSwapRateHelper2("LIBOR3M_SWAP_7Y",C20,,"7Y","JoinHolidays(UnitedStates::Settlement,UnitedKingdom::Settlement)","Semiannual","Modified Following","30/360 (USA)",Indexes!$B$16,0,"0D",Indexes!$B$5,"LastRelevantDate",,FALSE,'USD-FedFunds'!$B$32) -> LIBOR3M_SWAP_7Y#0000 | F20: =_xll.ohRangeRetrieveError(E20)
A21: Swap | B21: IR_SWAP/RATE/USD/2D/3M/8Y | C21: =MarketData!$E$176 -> USD-LIBOR-3M_IR_SWAP_RATE_USD_2D_3M_8Y#0000 | E21: =_xll.qlSwapRateHelper2("LIBOR3M_SWAP_8Y",C21,,"8Y","JoinHolidays(UnitedStates::Settlement,UnitedKingdom::Settlement)","Semiannual","Modified Following","30/360 (USA)",Indexes!$B$16,0,"0D",Indexes!$B$5,"LastRelevantDate",,FALSE,'USD-FedFunds'!$B$32) -> LIBOR3M_SWAP_8Y#0000 | F21: =_xll.ohRangeRetrieveError(E21)
A22: Swap | B22: IR_SWAP/RATE/USD/2D/3M/9Y | C22: =MarketData!$E$177 -> USD-LIBOR-3M_IR_SWAP_RATE_USD_2D_3M_9Y#0000 | E22: =_xll.qlSwapRateHelper2("LIBOR3M_SWAP_9Y",C22,,"9Y","JoinHolidays(UnitedStates::Settlement,UnitedKingdom::Settlement)","Semiannual","Modified Following","30/360 (USA)",Indexes!$B$16,0,"0D",Indexes!$B$5,"LastRelevantDate",,FALSE,'USD-FedFunds'!$B$32) -> LIBOR3M_SWAP_9Y#0000 | F22: =_xll.ohRangeRetrieveError(E22)
A23: Swap | B23: IR_SWAP/RATE/USD/2D/3M/10Y | C23: =MarketData!$E$178 -> USD-LIBOR-3M_IR_SWAP_RATE_USD_2D_3M_10Y#0000 | E23: =_xll.qlSwapRateHelper2("LIBOR3M_SWAP_10Y",C23,,"10Y","JoinHolidays(UnitedStates::Settlement,UnitedKingdom::Settlement)","Semiannual","Modified Following","30/360 (USA)",Indexes!$B$16,0,"0D",Indexes!$B$5,"LastRelevantDate",,FALSE,'USD-FedFunds'!$B$32) -> LIBOR3M_SWAP_10Y#0000 | F23: =_xll.ohRangeRetrieveError(E23)
A24: Swap | B24: IR_SWAP/RATE/USD/2D/3M/12Y | C24: =MarketData!$E$179 -> USD-LIBOR-3M_IR_SWAP_RATE_USD_2D_3M_12Y#0000 | E24: =_xll.qlSwapRateHelper2("LIBOR3M_SWAP_12Y",C24,,"12Y","JoinHolidays(UnitedStates::Settlement,UnitedKingdom::Settlement)","Semiannual","Modified Following","30/360 (USA)",Indexes!$B$16,0,"0D",Indexes!$B$5,"LastRelevantDate",,FALSE,'USD-FedFunds'!$B$32) -> LIBOR3M_SWAP_12Y#0000 | F24: =_xll.ohRangeRetrieveError(E24)
A25: Swap | B25: IR_SWAP/RATE/USD/2D/3M/15Y | C25: =MarketData!$E$180 -> USD-LIBOR-3M_IR_SWAP_RATE_USD_2D_3M_15Y#0000 | E25: =_xll.qlSwapRateHelper2("LIBOR3M_SWAP_15Y",C25,,"15Y","JoinHolidays(UnitedStates::Settlement,UnitedKingdom::Settlement)","Semiannual","Modified Following","30/360 (USA)",Indexes!$B$16,0,"0D",Indexes!$B$5,"LastRelevantDate",,FALSE,'USD-FedFunds'!$B$32) -> LIBOR3M_SWAP_15Y#0000 | F25: =_xll.ohRangeRetrieveError(E25)
A26: Swap | B26: IR_SWAP/RATE/USD/2D/3M/20Y | C26: =MarketData!$E$181 -> USD-LIBOR-3M_IR_SWAP_RATE_USD_2D_3M_20Y#0000 | E26: =_xll.qlSwapRateHelper2("LIBOR3M_SWAP_20Y",C26,,"20Y","JoinHolidays(UnitedStates::Settlement,UnitedKingdom::Settlement)","Semiannual","Modified Following","30/360 (USA)",Indexes!$B$16,0,"0D",Indexes!$B$5,"LastRelevantDate",,FALSE,'USD-FedFunds'!$B$32) -> LIBOR3M_SWAP_20Y#0000 | F26: =_xll.ohRangeRetrieveError(E26)
A27: Swap | B27: IR_SWAP/RATE/USD/2D/3M/25Y | C27: =MarketData!$E$182 -> USD-LIBOR-3M_IR_SWAP_RATE_USD_2D_3M_25Y#0000 | E27: =_xll.qlSwapRateHelper2("LIBOR3M_SWAP_25Y",C27,,"25Y","JoinHolidays(UnitedStates::Settlement,UnitedKingdom::Settlement)","Semiannual","Modified Following","30/360 (USA)",Indexes!$B$16,0,"0D",Indexes!$B$5,"LastRelevantDate",,FALSE,'USD-FedFunds'!$B$32) -> LIBOR3M_SWAP_25Y#0000 | F27: =_xll.ohRangeRetrieveError(E27)
A28: Swap | B28: IR_SWAP/RATE/USD/2D/3M/30Y | C28: =MarketData!$E$183 -> USD-LIBOR-3M_IR_SWAP_RATE_USD_2D_3M_30Y#0000 | E28: =_xll.qlSwapRateHelper2("LIBOR3M_SWAP_30Y",C28,,"30Y","JoinHolidays(UnitedStates::Settlement,UnitedKingdom::Settlement)","Semiannual","Modified Following","30/360 (USA)",Indexes!$B$16,0,"0D",Indexes!$B$5,"LastRelevantDate",,FALSE,'USD-FedFunds'!$B$32) -> LIBOR3M_SWAP_30Y#0000 | F28: =_xll.ohRangeRetrieveError(E28)
A29: Swap | B29: IR_SWAP/RATE/USD/2D/3M/40Y | C29: =MarketData!$E$184 -> USD-LIBOR-3M_IR_SWAP_RATE_USD_2D_3M_40Y#0000 | E29: =_xll.qlSwapRateHelper2("LIBOR3M_SWAP_40Y",C29,,"40Y","JoinHolidays(UnitedStates::Settlement,UnitedKingdom::Settlement)","Semiannual","Modified Following","30/360 (USA)",Indexes!$B$16,0,"0D",Indexes!$B$5,"LastRelevantDate",,FALSE,'USD-FedFunds'!$B$32) -> LIBOR3M_SWAP_40Y#0000 | F29: =_xll.ohRangeRetrieveError(E29)
A30: Swap | B30: IR_SWAP/RATE/USD/2D/3M/50Y | C30: =MarketData!$E$185 -> USD-LIBOR-3M_IR_SWAP_RATE_USD_2D_3M_50Y#0000 | E30: =_xll.qlSwapRateHelper2("LIBOR3M_SWAP_50Y",C30,,"50Y","JoinHolidays(UnitedStates::Settlement,UnitedKingdom::Settlement)","Semiannual","Modified Following","30/360 (USA)",Indexes!$B$16,0,"0D",Indexes!$B$5,"LastRelevantDate",,FALSE,'USD-FedFunds'!$B$32) -> LIBOR3M_SWAP_50Y#0000 | F30: =_xll.ohRangeRetrieveError(E30)
A32: Curve | B32: =_xll.qlPiecewiseYieldCurve("C_USD-LIBOR-3M",0,"UnitedKingdom::Exchange",E5:E30,"Actual/365 (Fixed)",,,"Discount","LogLinear",FALSE,Indexes!$B$31) -> C_USD-LIBOR-3M#0000 | C32: =_xll.ohRangeRetrieveError(B32) | D32: =_xll.qlExtrapolatorEnableExtrapolation(B32,TRUE) -> TRUE
A33: Link handle H_USD-LIBOR-3M | B33: =_xll.qlRelinkableHandleLinkTo(Indexes!$B$7,B32,D32) -> TRUE | C33: =_xll.ohRangeRetrieveError(B33)
A35: Date | B35: ORE discount factor | C35: Excel discount factor | D35: Difference | E35: Rel. difference
A36: =DATE(2020,4,2) -> 43923 | B36: 0.99503874 | C36: =_xll.qlYieldTSDiscount($B$32,A36,TRUE,$B$33) -> 0.99503874 | D36: =C36-B36 -> 0 | E36: =D36/B36 -> 0
A37: =DATE(2020,5,4) -> 43955 | B37: 0.99368884 | C37: =_xll.qlYieldTSDiscount($B$32,A37,TRUE,$B$33) -> 0.99368884 | D37: =C37-B37 -> 0 | E37: =D37/B37 -> 0
A38: =DATE(2020,6,2) -> 43984 | B38: 0.9922574 | C38: =_xll.qlYieldTSDiscount($B$32,A38,TRUE,$B$33) -> 0.9922574 | D38: =C38-B38 -> 0 | E38: =D38/B38 -> 0
A39: =DATE(2020,7,2) -> 44014 | B39: 0.99073375 | C39: =_xll.qlYieldTSDiscount($B$32,A39,TRUE,$B$33) -> 0.99073375 | D39: =C39-B39 -> 0 | E39: =D39/B39 -> 0
A40: =DATE(2020,8,4) -> 44047 | B40: 0.98941566 | C40: =_xll.qlYieldTSDiscount($B$32,A40,TRUE,$B$33) -> 0.98941566 | D40: =C40-B40 -> 0 | E40: =D40/B40 -> 0
A41: =DATE(2020,9,2) -> 44076 | B41: 0.98801803 | C41: =_xll.qlYieldTSDiscount($B$32,A41,TRUE,$B$33) -> 0.98801803 | D41: =C41-B41 -> 0 | E41: =D41/B41 -> 0
A42: =DATE(2020,10,2) -> 44106 | B42: 0.986526 | C42: =_xll.qlYieldTSDiscount($B$32,A42,TRUE,$B$33) -> 0.986526 | D42: =C42-B42 -> 0 | E42: =D42/B42 -> 0
A43: =DATE(2020,11,3) -> 44138 | B43: 0.985336 | C43: =_xll.qlYieldTSDiscount($B$32,A43,TRUE,$B$33) -> 0.985336 | D43: =C43-B43 -> 0 | E43: =D43/B43 -> 0
...

Sheet USD-LIBOR-6M
A1: USD-LIBOR-6M: Discount/LogLinear, A365, extrapolation; discount curve USD-FedFunds; deposit 6M, FRAs 1x7..12x18, 3M/6M tenor basis 2Y-30Y
A2: USD-LIBOR-3M-6M-BASIS: pay USD-LIBOR-6M (bootstrapped), receive USD-LIBOR-3M (given) compounded to 6M, spread on receive leg, telescopic dates.
A4: Segment | B4: Quote | C4: Rate | E4: Helper | F4: Error
A5: Deposit | B5: MM/RATE/USD/2D/6M | C5: =MarketData!$E$186 -> USD-LIBOR-6M_MM_RATE_USD_2D_6M#0000 | E5: =_xll.qlDepositRateHelper2("LIBOR6M_DEP",C5,"6M",2,"UnitedKingdom::Exchange","Modified Following",TRUE,"Actual/360",FALSE,Indexes!$B$31) -> LIBOR6M_DEP#0000 | F5: =_xll.ohRangeRetrieveError(E5)
A6: FRA | B6: FRA/RATE/USD/1M/6M | C6: =MarketData!$E$187 -> USD-LIBOR-6M_FRA_RATE_USD_1M_6M#0000 | E6: =_xll.qlFraRateHelper("LIBOR6M_FRA_1M",C6,"1M",Indexes!$B$17,"LastRelevantDate",,FALSE,Indexes!$B$31) -> LIBOR6M_FRA_1M#0000 | F6: =_xll.ohRangeRetrieveError(E6)
A7: FRA | B7: FRA/RATE/USD/2M/6M | C7: =MarketData!$E$188 -> USD-LIBOR-6M_FRA_RATE_USD_2M_6M#0000 | E7: =_xll.qlFraRateHelper("LIBOR6M_FRA_2M",C7,"2M",Indexes!$B$17,"LastRelevantDate",,FALSE,Indexes!$B$31) -> LIBOR6M_FRA_2M#0000 | F7: =_xll.ohRangeRetrieveError(E7)
A8: FRA | B8: FRA/RATE/USD/3M/6M | C8: =MarketData!$E$189 -> USD-LIBOR-6M_FRA_RATE_USD_3M_6M#0000 | E8: =_xll.qlFraRateHelper("LIBOR6M_FRA_3M",C8,"3M",Indexes!$B$17,"LastRelevantDate",,FALSE,Indexes!$B$31) -> LIBOR6M_FRA_3M#0000 | F8: =_xll.ohRangeRetrieveError(E8)
A9: FRA | B9: FRA/RATE/USD/4M/6M | C9: =MarketData!$E$190 -> USD-LIBOR-6M_FRA_RATE_USD_4M_6M#0000 | E9: =_xll.qlFraRateHelper("LIBOR6M_FRA_4M",C9,"4M",Indexes!$B$17,"LastRelevantDate",,FALSE,Indexes!$B$31) -> LIBOR6M_FRA_4M#0000 | F9: =_xll.ohRangeRetrieveError(E9)
A10: FRA | B10: FRA/RATE/USD/5M/6M | C10: =MarketData!$E$191 -> USD-LIBOR-6M_FRA_RATE_USD_5M_6M#0000 | E10: =_xll.qlFraRateHelper("LIBOR6M_FRA_5M",C10,"5M",Indexes!$B$17,"LastRelevantDate",,FALSE,Indexes!$B$31) -> LIBOR6M_FRA_5M#0000 | F10: =_xll.ohRangeRetrieveError(E10)
A11: FRA | B11: FRA/RATE/USD/6M/6M | C11: =MarketData!$E$192 -> USD-LIBOR-6M_FRA_RATE_USD_6M_6M#0000 | E11: =_xll.qlFraRateHelper("LIBOR6M_FRA_6M",C11,"6M",Indexes!$B$17,"LastRelevantDate",,FALSE,Indexes!$B$31) -> LIBOR6M_FRA_6M#0000 | F11: =_xll.ohRangeRetrieveError(E11)
A12: FRA | B12: FRA/RATE/USD/9M/6M | C12: =MarketData!$E$193 -> USD-LIBOR-6M_FRA_RATE_USD_9M_6M#0000 | E12: =_xll.qlFraRateHelper("LIBOR6M_FRA_9M",C12,"9M",Indexes!$B$17,"LastRelevantDate",,FALSE,Indexes!$B$31) -> LIBOR6M_FRA_9M#0000 | F12: =_xll.ohRangeRetrieveError(E12)
A13: FRA | B13: FRA/RATE/USD/12M/6M | C13: =MarketData!$E$194 -> USD-LIBOR-6M_FRA_RATE_USD_12M_6M#0000 | E13: =_xll.qlFraRateHelper("LIBOR6M_FRA_12M",C13,"12M",Indexes!$B$17,"LastRelevantDate",,FALSE,Indexes!$B$31) -> LIBOR6M_FRA_12M#0000 | F13: =_xll.ohRangeRetrieveError(E13)
A14: Tenor basis | B14: BASIS_SWAP/BASIS_SPREAD/3M/6M/USD/2Y | C14: =MarketData!$E$195 -> USD-LIBOR-6M_BASIS_SWAP_BASIS_SPREAD_3M_6M_USD_2Y#0000 | E14: =_xll.qlTenorBasisSwapHelper("LIBOR6M_TBS_2Y",C14,"2Y",Indexes!$B$17,Indexes!$B$16,Indexes!$B$5,TRUE,FALSE,"6M","6M",TRUE,"Compounding",FALSE,TRUE,FALSE,'USD-FedFunds'!$B$32) -> LIBOR6M_TBS_2Y#0000 | F14: =_xll.ohRangeRetrieveError(E14)
A15: Tenor basis | B15: BASIS_SWAP/BASIS_SPREAD/3M/6M/USD/3Y | C15: =MarketData!$E$196 -> USD-LIBOR-6M_BASIS_SWAP_BASIS_SPREAD_3M_6M_USD_3Y#0000 | E15: =_xll.qlTenorBasisSwapHelper("LIBOR6M_TBS_3Y",C15,"3Y",Indexes!$B$17,Indexes!$B$16,Indexes!$B$5,TRUE,FALSE,"6M","6M",TRUE,"Compounding",FALSE,TRUE,FALSE,'USD-FedFunds'!$B$32) -> LIBOR6M_TBS_3Y#0000 | F15: =_xll.ohRangeRetrieveError(E15)
A16: Tenor basis | B16: BASIS_SWAP/BASIS_SPREAD/3M/6M/USD/4Y | C16: =MarketData!$E$197 -> USD-LIBOR-6M_BASIS_SWAP_BASIS_SPREAD_3M_6M_USD_4Y#0000 | E16: =_xll.qlTenorBasisSwapHelper("LIBOR6M_TBS_4Y",C16,"4Y",Indexes!$B$17,Indexes!$B$16,Indexes!$B$5,TRUE,FALSE,"6M","6M",TRUE,"Compounding",FALSE,TRUE,FALSE,'USD-FedFunds'!$B$32) -> LIBOR6M_TBS_4Y#0000 | F16: =_xll.ohRangeRetrieveError(E16)
A17: Tenor basis | B17: BASIS_SWAP/BASIS_SPREAD/3M/6M/USD/5Y | C17: =MarketData!$E$198 -> USD-LIBOR-6M_BASIS_SWAP_BASIS_SPREAD_3M_6M_USD_5Y#0000 | E17: =_xll.qlTenorBasisSwapHelper("LIBOR6M_TBS_5Y",C17,"5Y",Indexes!$B$17,Indexes!$B$16,Indexes!$B$5,TRUE,FALSE,"6M","6M",TRUE,"Compounding",FALSE,TRUE,FALSE,'USD-FedFunds'!$B$32) -> LIBOR6M_TBS_5Y#0000 | F17: =_xll.ohRangeRetrieveError(E17)
A18: Tenor basis | B18: BASIS_SWAP/BASIS_SPREAD/3M/6M/USD/6Y | C18: =MarketData!$E$199 -> USD-LIBOR-6M_BASIS_SWAP_BASIS_SPREAD_3M_6M_USD_6Y#0000 | E18: =_xll.qlTenorBasisSwapHelper("LIBOR6M_TBS_6Y",C18,"6Y",Indexes!$B$17,Indexes!$B$16,Indexes!$B$5,TRUE,FALSE,"6M","6M",TRUE,"Compounding",FALSE,TRUE,FALSE,'USD-FedFunds'!$B$32) -> LIBOR6M_TBS_6Y#0000 | F18: =_xll.ohRangeRetrieveError(E18)
A19: Tenor basis | B19: BASIS_SWAP/BASIS_SPREAD/3M/6M/USD/7Y | C19: =MarketData!$E$200 -> USD-LIBOR-6M_BASIS_SWAP_BASIS_SPREAD_3M_6M_USD_7Y#0000 | E19: =_xll.qlTenorBasisSwapHelper("LIBOR6M_TBS_7Y",C19,"7Y",Indexes!$B$17,Indexes!$B$16,Indexes!$B$5,TRUE,FALSE,"6M","6M",TRUE,"Compounding",FALSE,TRUE,FALSE,'USD-FedFunds'!$B$32) -> LIBOR6M_TBS_7Y#0000 | F19: =_xll.ohRangeRetrieveError(E19)
A20: Tenor basis | B20: BASIS_SWAP/BASIS_SPREAD/3M/6M/USD/8Y | C20: =MarketData!$E$201 -> USD-LIBOR-6M_BASIS_SWAP_BASIS_SPREAD_3M_6M_USD_8Y#0000 | E20: =_xll.qlTenorBasisSwapHelper("LIBOR6M_TBS_8Y",C20,"8Y",Indexes!$B$17,Indexes!$B$16,Indexes!$B$5,TRUE,FALSE,"6M","6M",TRUE,"Compounding",FALSE,TRUE,FALSE,'USD-FedFunds'!$B$32) -> LIBOR6M_TBS_8Y#0000 | F20: =_xll.ohRangeRetrieveError(E20)
A21: Tenor basis | B21: BASIS_SWAP/BASIS_SPREAD/3M/6M/USD/9Y | C21: =MarketData!$E$202 -> USD-LIBOR-6M_BASIS_SWAP_BASIS_SPREAD_3M_6M_USD_9Y#0000 | E21: =_xll.qlTenorBasisSwapHelper("LIBOR6M_TBS_9Y",C21,"9Y",Indexes!$B$17,Indexes!$B$16,Indexes!$B$5,TRUE,FALSE,"6M","6M",TRUE,"Compounding",FALSE,TRUE,FALSE,'USD-FedFunds'!$B$32) -> LIBOR6M_TBS_9Y#0000 | F21: =_xll.ohRangeRetrieveError(E21)
A22: Tenor basis | B22: BASIS_SWAP/BASIS_SPREAD/3M/6M/USD/10Y | C22: =MarketData!$E$203 -> USD-LIBOR-6M_BASIS_SWAP_BASIS_SPREAD_3M_6M_USD_10Y#0000 | E22: =_xll.qlTenorBasisSwapHelper("LIBOR6M_TBS_10Y",C22,"10Y",Indexes!$B$17,Indexes!$B$16,Indexes!$B$5,TRUE,FALSE,"6M","6M",TRUE,"Compounding",FALSE,TRUE,FALSE,'USD-FedFunds'!$B$32) -> LIBOR6M_TBS_10Y#0000 | F22: =_xll.ohRangeRetrieveError(E22)
A23: Tenor basis | B23: BASIS_SWAP/BASIS_SPREAD/3M/6M/USD/11Y | C23: =MarketData!$E$204 -> USD-LIBOR-6M_BASIS_SWAP_BASIS_SPREAD_3M_6M_USD_11Y#0000 | E23: =_xll.qlTenorBasisSwapHelper("LIBOR6M_TBS_11Y",C23,"11Y",Indexes!$B$17,Indexes!$B$16,Indexes!$B$5,TRUE,FALSE,"6M","6M",TRUE,"Compounding",FALSE,TRUE,FALSE,'USD-FedFunds'!$B$32) -> LIBOR6M_TBS_11Y#0000 | F23: =_xll.ohRangeRetrieveError(E23)
A24: Tenor basis | B24: BASIS_SWAP/BASIS_SPREAD/3M/6M/USD/12Y | C24: =MarketData!$E$205 -> USD-LIBOR-6M_BASIS_SWAP_BASIS_SPREAD_3M_6M_USD_12Y#0000 | E24: =_xll.qlTenorBasisSwapHelper("LIBOR6M_TBS_12Y",C24,"12Y",Indexes!$B$17,Indexes!$B$16,Indexes!$B$5,TRUE,FALSE,"6M","6M",TRUE,"Compounding",FALSE,TRUE,FALSE,'USD-FedFunds'!$B$32) -> LIBOR6M_TBS_12Y#0000 | F24: =_xll.ohRangeRetrieveError(E24)
A25: Tenor basis | B25: BASIS_SWAP/BASIS_SPREAD/3M/6M/USD/15Y | C25: =MarketData!$E$206 -> USD-LIBOR-6M_BASIS_SWAP_BASIS_SPREAD_3M_6M_USD_15Y#0000 | E25: =_xll.qlTenorBasisSwapHelper("LIBOR6M_TBS_15Y",C25,"15Y",Indexes!$B$17,Indexes!$B$16,Indexes!$B$5,TRUE,FALSE,"6M","6M",TRUE,"Compounding",FALSE,TRUE,FALSE,'USD-FedFunds'!$B$32) -> LIBOR6M_TBS_15Y#0000 | F25: =_xll.ohRangeRetrieveError(E25)
A26: Tenor basis | B26: BASIS_SWAP/BASIS_SPREAD/3M/6M/USD/20Y | C26: =MarketData!$E$207 -> USD-LIBOR-6M_BASIS_SWAP_BASIS_SPREAD_3M_6M_USD_20Y#0000 | E26: =_xll.qlTenorBasisSwapHelper("LIBOR6M_TBS_20Y",C26,"20Y",Indexes!$B$17,Indexes!$B$16,Indexes!$B$5,TRUE,FALSE,"6M","6M",TRUE,"Compounding",FALSE,TRUE,FALSE,'USD-FedFunds'!$B$32) -> LIBOR6M_TBS_20Y#0000 | F26: =_xll.ohRangeRetrieveError(E26)
A27: Tenor basis | B27: BASIS_SWAP/BASIS_SPREAD/3M/6M/USD/25Y | C27: =MarketData!$E$208 -> USD-LIBOR-6M_BASIS_SWAP_BASIS_SPREAD_3M_6M_USD_25Y#0000 | E27: =_xll.qlTenorBasisSwapHelper("LIBOR6M_TBS_25Y",C27,"25Y",Indexes!$B$17,Indexes!$B$16,Indexes!$B$5,TRUE,FALSE,"6M","6M",TRUE,"Compounding",FALSE,TRUE,FALSE,'USD-FedFunds'!$B$32) -> LIBOR6M_TBS_25Y#0000 | F27: =_xll.ohRangeRetrieveError(E27)
A28: Tenor basis | B28: BASIS_SWAP/BASIS_SPREAD/3M/6M/USD/30Y | C28: =MarketData!$E$209 -> USD-LIBOR-6M_BASIS_SWAP_BASIS_SPREAD_3M_6M_USD_30Y#0000 | E28: =_xll.qlTenorBasisSwapHelper("LIBOR6M_TBS_30Y",C28,"30Y",Indexes!$B$17,Indexes!$B$16,Indexes!$B$5,TRUE,FALSE,"6M","6M",TRUE,"Compounding",FALSE,TRUE,FALSE,'USD-FedFunds'!$B$32) -> LIBOR6M_TBS_30Y#0000 | F28: =_xll.ohRangeRetrieveError(E28)
A30: Curve | B30: =_xll.qlPiecewiseYieldCurve("C_USD-LIBOR-6M",0,"UnitedKingdom::Exchange",E5:E28,"Actual/365 (Fixed)",,,"Discount","LogLinear",FALSE,Indexes!$B$31) -> C_USD-LIBOR-6M#0000 | C30: =_xll.ohRangeRetrieveError(B30) | D30: =_xll.qlExtrapolatorEnableExtrapolation(B30,TRUE) -> TRUE
A31: Link handle H_USD-LIBOR-6M | B31: =_xll.qlRelinkableHandleLinkTo(Indexes!$B$8,B30,D30) -> TRUE | C31: =_xll.ohRangeRetrieveError(B31)
A33: Date | B33: ORE discount factor | C33: Excel discount factor | D33: Difference | E33: Rel. difference
A34: =DATE(2020,7,2) -> 44014 | B34: 0.99028566 | C34: =_xll.qlYieldTSDiscount($B$30,A34,TRUE,$B$31) -> 0.99028566 | D34: =C34-B34 -> 0 | E34: =D34/B34 -> 0
A35: =DATE(2020,8,3) -> 44046 | B35: 0.98911889 | C35: =_xll.qlYieldTSDiscount($B$30,A35,TRUE,$B$31) -> 0.98911889 | D35: =C35-B35 -> 0 | E35: =D35/B35 -> 0
A36: =DATE(2020,9,2) -> 44076 | B36: 0.98780546 | C36: =_xll.qlYieldTSDiscount($B$30,A36,TRUE,$B$31) -> 0.98780546 | D36: =C36-B36 -> 0 | E36: =D36/B36 -> 0
A37: =DATE(2020,10,2) -> 44106 | B37: 0.9863182 | C37: =_xll.qlYieldTSDiscount($B$30,A37,TRUE,$B$31) -> 0.9863182 | D37: =C37-B37 -> 0 | E37: =D37/B37 -> 0
